Workbook

Sheet Calculation
W1: AFS Days | X1: Shipment Plan Days | AC1: Bunch Qty | AF1: to ship
W2: 30 | X2: 40 | AC2: 2 | AF2: =SUM(AF4:AF833) -> 3148
A3: Group Name | B3: SKU | C3: Title | D3: Category | E3: Int – WH | F3: Dec – WH | G3: Non Apron Qty | H3: APR- Sky Blue | I3: APR- Dark Blue | J3: APR- Brown | K3: APR- Green | L3: APR- Tan | M3: APR- Black | N3: APR- Red | O3: APR- Grey | P3: weight | Q3: Total Weight | S3: HSN | T3: GST | U3: COST | V3: SKU | W3: Title | X3: Tra. Qty | Y3: quantity | Z3: Available Qty | AA3: Fulfilment ID | AB3: Sale-Total | AC3: Sale-WH | AD3: Ship – WH | AE3: Sum | AF3: Final – WH
A4: APR- Black | B4: Apron_Black | C4: CRASOME Polyester Kitchen Apron for Men Women Chef Cooking Restaurants gardening workshop barbers With Pockets and Adjustable Strap ( Black ) | D4: Apron | E4: =IF(ISNUMBER(AD4),IF(AD4>=0,IF(AD4=0,1,INT(AD4/$AC$2)),""),"") | F4: =IF(E4="","",IF(AD4=0,0,AD4/$AC$2-E4)) | G4: =IF(ISERROR(SEARCH("Apron",D4)),AF4,"") | M4: =IF(ISNUMBER($AF4),1*$AF4,"") | P4: {=XLOOKUP(B4,Weight!B:B,Weight!D:D,"#N/A",0)} -> 140 | Q4: =IF(AF4="","",AF4*P4) | S4: 392620 | T4: 12 | U4: 60 | V4: =B4 -> Apron_Black | W4: =C4 -> CRASOME Polyester Kitchen Apron for Men Women Chef Cooking Restaurants gardening workshop barbers With Pockets and Adjustable Strap ( Black ) | X4: =SUMIFS('Transit Shipment'!$B$10:$B$1048462,'Transit Shipment'!$A$10:$A$1048462,B4,'Transit Shipment'!$C$10:$C$1048462,AA4) -> 0 | Y4: =IF(SUMIFS(DIH!$S$2:$S833,DIH!$D$2:$D833,B4,DIH!$U$2:$U833,AA4)>0,SUMIFS(DIH!$S$2:$S833,DIH!$D$2:$D833,B4,DIH!$U$2:$U833,AA4),0) -> 2 | Z4: =SUM(X4:Y4) -> 2 | AA4: AMD2 | AB4: =IF(ISNA(VLOOKUP($B4,'Business Report'!$D$2:$J$202,2,0)),"",VLOOKUP($B4,'Business Report'!$D$2:$J$202,2,0)) -> 117 | AC4: =SUMIFS(AFS!$P$2:$P$6260,AFS!$N$2:$N$6260,B4,AFS!$AT$2:$AT$6260,AA4) -> 0 | AD4: =CEILING(AC4/$W$2*$X$2,1)-sum(X4:Y4) -> -2 | AF4: =IF(ISNUMBER(AD4),IF(AD4<=0,"",IF(F4="","",E4*$AC$2+IF(F4>0,$AC$2,0))))
A5: APR- Black | B5: Apron_Black | C5: CRASOME Polyester Kitchen Apron for Men Women Chef Cooking Restaurants gardening workshop barbers With Pockets and Adjustable Strap ( Black ) | D5: Apron | E5: =IF(ISNUMBER(AD5),IF(AD5>=0,IF(AD5=0,1,INT(AD5/$AC$2)),""),"") -> 0 | F5: =IF(E5="","",IF(AD5=0,0,AD5/$AC$2-E5)) -> 0.5 | G5: =IF(ISERROR(SEARCH("Apron",D5)),AF5,"") | M5: =IF(ISNUMBER($AF5),1*$AF5,"") -> 2 | P5: {=XLOOKUP(B5,Weight!B:B,Weight!D:D,"#N/A",0)} -> 140 | Q5: =IF(AF5="","",AF5*P5) -> 280 | S5: 392620 | T5: 12 | U5: 60 | X5: =SUMIFS('Transit Shipment'!$B$10:$B$1048462,'Transit Shipment'!$A$10:$A$1048462,B5,'Transit Shipment'!$C$10:$C$1048462,AA5) -> 0 | Y5: =IF(SUMIFS(DIH!$S$2:$S833,DIH!$D$2:$D833,B5,DIH!$U$2:$U833,AA5)>0,SUMIFS(DIH!$S$2:$S833,DIH!$D$2:$D833,B5,DIH!$U$2:$U833,AA5),0) -> 7 | Z5: =SUM(X5:Y5) -> 7 | AA5: BLR8 | AB5: =IF(ISNA(VLOOKUP($B5,'Business Report'!$D$2:$J$202,2,0)),"",VLOOKUP($B5,'Business Report'!$D$2:$J$202,2,0)) -> 117 | AC5: =SUMIFS(AFS!$P$2:$P$6260,AFS!$N$2:$N$6260,B5,AFS!$AT$2:$AT$6260,AA5) -> 6 | AD5: =CEILING(AC5/$W$2*$X$2,1)-sum(X5:Y5) -> 1 | AF5: =IF(ISNUMBER(AD5),IF(AD5<=0,"",IF(F5="","",E5*$AC$2+IF(F5>0,$AC$2,0)))) -> 2
A6: APR- Black | B6: Apron_Black | C6: CRASOME Polyester Kitchen Apron for Men Women Chef Cooking Restaurants gardening workshop barbers With Pockets and Adjustable Strap ( Black ) | D6: Apron | E6: =IF(ISNUMBER(AD6),IF(AD6>=0,IF(AD6=0,1,INT(AD6/$AC$2)),""),"") -> 2 | F6: =IF(E6="","",IF(AD6=0,0,AD6/$AC$2-E6)) -> 0.5 | G6: =IF(ISERROR(SEARCH("Apron",D6)),AF6,"") | M6: =IF(ISNUMBER($AF6),1*$AF6,"") -> 6 | P6: {=XLOOKUP(B6,Weight!B:B,Weight!D:D,"#N/A",0)} -> 140 | Q6: =IF(AF6="","",AF6*P6) -> 840 | S6: 392620 | T6: 12 | U6: 60 | X6: =SUMIFS('Transit Shipment'!$B$10:$B$1048462,'Transit Shipment'!$A$10:$A$1048462,B6,'Transit Shipment'!$C$10:$C$1048462,AA6) -> 0 | Y6: =IF(SUMIFS(DIH!$S$2:$S833,DIH!$D$2:$D833,B6,DIH!$U$2:$U833,AA6)>0,SUMIFS(DIH!$S$2:$S833,DIH!$D$2:$D833,B6,DIH!$U$2:$U833,AA6),0) -> 2 | Z6: =SUM(X6:Y6) -> 2 | AA6: BLR7 | AB6: =IF(ISNA(VLOOKUP($B6,'Business Report'!$D$2:$J$202,2,0)),"",VLOOKUP($B6,'Business Report'!$D$2:$J$202,2,0)) -> 117 | AC6: =SUMIFS(AFS!$P$2:$P$6260,AFS!$N$2:$N$6260,B6,AFS!$AT$2:$AT$6260,AA6) -> 5 | AD6: =CEILING(AC6/$W$2*$X$2,1)-sum(X6:Y6) -> 5 | AF6: =IF(ISNUMBER(AD6),IF(AD6<=0,"",IF(F6="","",E6*$AC$2+IF(F6>0,$AC$2,0)))) -> 6
A7: APR- Black | B7: Apron_Black | C7: CRASOME Polyester Kitchen Apron for Men Women Chef Cooking Restaurants gardening workshop barbers With Pockets and Adjustable Strap ( Black ) | D7: Apron | E7: =IF(ISNUMBER(AD7),IF(AD7>=0,IF(AD7=0,1,INT(AD7/$AC$2)),""),"") -> 0 | F7: =IF(E7="","",IF(AD7=0,0,AD7/$AC$2-E7)) -> 0.5 | G7: =IF(ISERROR(SEARCH("Apron",D7)),AF7,"") | M7: =IF(ISNUMBER($AF7),1*$AF7,"") -> 2 | P7: {=XLOOKUP(B7,Weight!B:B,Weight!D:D,"#N/A",0)} -> 140 | Q7: =IF(AF7="","",AF7*P7) -> 280 | S7: 392620 | T7: 12 | U7: 60 | X7: =SUMIFS('Transit Shipment'!$B$10:$B$1048462,'Transit Shipment'!$A$10:$A$1048462,B7,'Transit Shipment'!$C$10:$C$1048462,AA7) -> 0 | Y7: =IF(SUMIFS(DIH!$S$2:$S833,DIH!$D$2:$D833,B7,DIH!$U$2:$U833,AA7)>0,SUMIFS(DIH!$S$2:$S833,DIH!$D$2:$D833,B7,DIH!$U$2:$U833,AA7),0) -> 1 | Z7: =SUM(X7:Y7) -> 1 | AA7: CJB1 | AB7: =IF(ISNA(VLOOKUP($B7,'Business Report'!$D$2:$J$202,2,0)),"",VLOOKUP($B7,'Business Report'!$D$2:$J$202,2,0)) -> 117 | AC7: =SUMIFS(AFS!$P$2:$P$6260,AFS!$N$2:$N$6260,B7,AFS!$AT$2:$AT$6260,AA7) -> 1 | AD7: =CEILING(AC7/$W$2*$X$2,1)-sum(X7:Y7) -> 1 | AF7: =IF(ISNUMBER(AD7),IF(AD7<=0,"",IF(F7="","",E7*$AC$2+IF(F7>0,$AC$2,0)))) -> 2
A8: APR- Black | B8: Apron_Black | C8: CRASOME Polyester Kitchen Apron for Men Women Chef Cooking Restaurants gardening workshop barbers With Pockets and Adjustable Strap ( Black ) | D8: Apron | E8: =IF(ISNUMBER(AD8),IF(AD8>=0,IF(AD8=0,1,INT(AD8/$AC$2)),""),"") -> 1 | F8: =IF(E8="","",IF(AD8=0,0,AD8/$AC$2-E8)) -> 0.5 | G8: =IF(ISERROR(SEARCH("Apron",D8)),AF8,"") | M8: =IF(ISNUMBER($AF8),1*$AF8,"") -> 4 | P8: {=XLOOKUP(B8,Weight!B:B,Weight!D:D,"#N/A",0)} -> 140 | Q8: =IF(AF8="","",AF8*P8) -> 560 | S8: 392620 | T8: 12 | U8: 60 | X8: =SUMIFS('Transit Shipment'!$B$10:$B$1048462,'Transit Shipment'!$A$10:$A$1048462,B8,'Transit Shipment'!$C$10:$C$1048462,AA8) -> 0 | Y8: =IF(SUMIFS(DIH!$S$2:$S833,DIH!$D$2:$D833,B8,DIH!$U$2:$U833,AA8)>0,SUMIFS(DIH!$S$2:$S833,DIH!$D$2:$D833,B8,DIH!$U$2:$U833,AA8),0) -> 1 | Z8: =SUM(X8:Y8) -> 1 | AA8: MAA4 | AB8: =IF(ISNA(VLOOKUP($B8,'Business Report'!$D$2:$J$202,2,0)),"",VLOOKUP($B8,'Business Report'!$D$2:$J$202,2,0)) -> 117 | AC8: =SUMIFS(AFS!$P$2:$P$6260,AFS!$N$2:$N$6260,B8,AFS!$AT$2:$AT$6260,AA8) -> 3 | AD8: =CEILING(AC8/$W$2*$X$2,1)-sum(X8:Y8) -> 3 | AF8: =IF(ISNUMBER(AD8),IF(AD8<=0,"",IF(F8="","",E8*$AC$2+IF(F8>0,$AC$2,0)))) -> 4
A9: APR- Black | B9: Apron_Black | C9: CRASOME Polyester Kitchen Apron for Men Women Chef Cooking Restaurants gardening workshop barbers With Pockets and Adjustable Strap ( Black ) | D9: Apron | E9: =IF(ISNUMBER(AD9),IF(AD9>=0,IF(AD9=0,1,INT(AD9/$AC$2)),""),"") -> 2 | F9: =IF(E9="","",IF(AD9=0,0,AD9/$AC$2-E9)) -> 0.5 | G9: =IF(ISERROR(SEARCH("Apron",D9)),AF9,"") | M9: =IF(ISNUMBER($AF9),1*$AF9,"") -> 6 | P9: {=XLOOKUP(B9,Weight!B:B,Weight!D:D,"#N/A",0)} -> 140 | Q9: =IF(AF9="","",AF9*P9) -> 840 | S9: 392620 | T9: 12 | U9: 60 | X9: =SUMIFS('Transit Shipment'!$B$10:$B$1048462,'Transit Shipment'!$A$10:$A$1048462,B9,'Transit Shipment'!$C$10:$C$1048462,AA9) -> 0 | Y9: =IF(SUMIFS(DIH!$S$2:$S833,DIH!$D$2:$D833,B9,DIH!$U$2:$U833,AA9)>0,SUMIFS(DIH!$S$2:$S833,DIH!$D$2:$D833,B9,DIH!$U$2:$U833,AA9),0) -> 1 | Z9: =SUM(X9:Y9) -> 1 | AA9: DEL4 | AB9: =IF(ISNA(VLOOKUP($B9,'Business Report'!$D$2:$J$202,2,0)),"",VLOOKUP($B9,'Business Report'!$D$2:$J$202,2,0)) -> 117 | AC9: =SUMIFS(AFS!$P$2:$P$6260,AFS!$N$2:$N$6260,B9,AFS!$AT$2:$AT$6260,AA9) -> 4 | AD9: =CEILING(AC9/$W$2*$X$2,1)-sum(X9:Y9) -> 5 | AF9: =IF(ISNUMBER(AD9),IF(AD9<=0,"",IF(F9="","",E9*$AC$2+IF(F9>0,$AC$2,0)))) -> 6
A10: APR- Black | B10: Apron_Black | C10: CRASOME Polyester Kitchen Apron for Men Women Chef Cooking Restaurants gardening workshop barbers With Pockets and Adjustable Strap ( Black ) | D10: Apron | E10: =IF(ISNUMBER(AD10),IF(AD10>=0,IF(AD10=0,1,INT(AD10/$AC$2)),""),"") | F10: =IF(E10="","",IF(AD10=0,0,AD10/$AC$2-E10)) | G10: =IF(ISERROR(SEARCH("Apron",D10)),AF10,"") | M10: =IF(ISNUMBER($AF10),1*$AF10,"") | P10: {=XLOOKUP(B10,Weight!B:B,Weight!D:D,"#N/A",0)} -> 140 | Q10: =IF(AF10="","",AF10*P10) | S10: 392620 | T10: 12 | U10: 60 | X10: =SUMIFS('Transit Shipment'!$B$10:$B$1048462,'Transit Shipment'!$A$10:$A$1048462,B10,'Transit Shipment'!$C$10:$C$1048462,AA10) -> 0 | Y10: =IF(SUMIFS(DIH!$S$2:$S833,DIH!$D$2:$D833,B10,DIH!$U$2:$U833,AA10)>0,SUMIFS(DIH!$S$2:$S833,DIH!$D$2:$D833,B10,DIH!$U$2:$U833,AA10),0) -> 4 | Z10: =SUM(X10:Y10) -> 4 | AA10: DEL5 | AB10: =IF(ISNA(VLOOKUP($B10,'Business Report'!$D$2:$J$202,2,0)),"",VLOOKUP($B10,'Business Report'!$D$2:$J$202,2,0)) -> 117 | AC10: =SUMIFS(AFS!$P$2:$P$6260,AFS!$N$2:$N$6260,B10,AFS!$AT$2:$AT$6260,AA10) -> 2 | AD10: =CEILING(AC10/$W$2*$X$2,1)-sum(X10:Y10) -> -1 | AF10: =IF(ISNUMBER(AD10),IF(AD10<=0,"",IF(F10="","",E10*$AC$2+IF(F10>0,$AC$2,0))))
A11: APR- Black | B11: Apron_Black | C11: CRASOME Polyester Kitchen Apron for Men Women Chef Cooking Restaurants gardening workshop barbers With Pockets and Adjustable Strap ( Black ) | D11: Apron | E11: =IF(ISNUMBER(AD11),IF(AD11>=0,IF(AD11=0,1,INT(AD11/$AC$2)),""),"") -> 3 | F11: =IF(E11="","",IF(AD11=0,0,AD11/$AC$2-E11)) -> 0.5 | G11: =IF(ISERROR(SEARCH("Apron",D11)),AF11,"") | M11: =IF(ISNUMBER($AF11),1*$AF11,"") -> 8 | P11: {=XLOOKUP(B11,Weight!B:B,Weight!D:D,"#N/A",0)} -> 140 | Q11: =IF(AF11="","",AF11*P11) -> 1120 | S11: 392620 | T11: 12 | U11: 60 | X11: =SUMIFS('Transit Shipment'!$B$10:$B$1048462,'Transit Shipment'!$A$10:$A$1048462,B11,'Transit Shipment'!$C$10:$C$1048462,AA11) -> 0 | Y11: =IF(SUMIFS(DIH!$S$2:$S833,DIH!$D$2:$D833,B11,DIH!$U$2:$U833,AA11)>0,SUMIFS(DIH!$S$2:$S833,DIH!$D$2:$D833,B11,DIH!$U$2:$U833,AA11),0) -> 5 | Z11: =SUM(X11:Y11) -> 5 | AA11: BOM5 | AB11: =IF(ISNA(VLOOKUP($B11,'Business Report'!$D$2:$J$202,2,0)),"",VLOOKUP($B11,'Business Report'!$D$2:$J$202,2,0)) -> 117 | AC11: =SUMIFS(AFS!$P$2:$P$6260,AFS!$N$2:$N$6260,B11,AFS!$AT$2:$AT$6260,AA11) -> 9 | AD11: =CEILING(AC11/$W$2*$X$2,1)-sum(X11:Y11) -> 7 | AF11: =IF(ISNUMBER(AD11),IF(AD11<=0,"",IF(F11="","",E11*$AC$2+IF(F11>0,$AC$2,0)))) -> 8
A12: APR- Black | B12: Apron_Black | C12: CRASOME Polyester Kitchen Apron for Men Women Chef Cooking Restaurants gardening workshop barbers With Pockets and Adjustable Strap ( Black ) | D12: Apron | E12: =IF(ISNUMBER(AD12),IF(AD12>=0,IF(AD12=0,1,INT(AD12/$AC$2)),""),"") -> 1 | F12: =IF(E12="","",IF(AD12=0,0,AD12/$AC$2-E12)) -> 0 | G12: =IF(ISERROR(SEARCH("Apron",D12)),AF12,"") | M12: =IF(ISNUMBER($AF12),1*$AF12,"") | P12: {=XLOOKUP(B12,Weight!B:B,Weight!D:D,"#N/A",0)} -> 140 | Q12: =IF(AF12="","",AF12*P12) | S12: 392620 | T12: 12 | U12: 60 | X12: =SUMIFS('Transit Shipment'!$B$10:$B$1048462,'Transit Shipment'!$A$10:$A$1048462,B12,'Transit Shipment'!$C$10:$C$1048462,AA12) -> 0 | Y12: =IF(SUMIFS(DIH!$S$2:$S833,DIH!$D$2:$D833,B12,DIH!$U$2:$U833,AA12)>0,SUMIFS(DIH!$S$2:$S833,DIH!$D$2:$D833,B12,DIH!$U$2:$U833,AA12),0) -> 0 | Z12: =SUM(X12:Y12) -> 0 | AA12: BOM7 | AB12: =IF(ISNA(VLOOKUP($B12,'Business Report'!$D$2:$J$202,2,0)),"",VLOOKUP($B12,'Business Report'!$D$2:$J$202,2,0)) -> 117 | AC12: =SUMIFS(AFS!$P$2:$P$6260,AFS!$N$2:$N$6260,B12,AFS!$AT$2:$AT$6260,AA12) -> 0 | AD12: =CEILING(AC12/$W$2*$X$2,1)-sum(X12:Y12) -> 0 | AE12: =SUM(AD4:AD12) -> 19 | AF12: =IF(ISNUMBER(AD12),IF(AD12<=0,"",IF(F12="","",E12*$AC$2+IF(F12>0,$AC$2,0))))
A13: APR- Dark Blue | B13: Apron_Blue | C13: CRASOME Polyester Kitchen Apron for Men Women Chef Cooking Restaurants gardening workshop barbers With Pockets and Adjustable Strap (Blue) | D13: Apron | E13: =IF(ISNUMBER(AD13),IF(AD13>=0,IF(AD13=0,1,INT(AD13/$AC$2)),""),"") | F13: =IF(E13="","",IF(AD13=0,0,AD13/$AC$2-E13)) | G13: =IF(ISERROR(SEARCH("Apron",D13)),AF13,"") | I13: =IF(ISNUMBER($AF13),1*$AF13,"") | P13: {=XLOOKUP(B13,Weight!B:B,Weight!D:D,"#N/A",0)} -> 140 | Q13: =IF(AF13="","",AF13*P13) | S13: 392620 | T13: 12 | U13: 60 | V13: =B13 -> Apron_Blue | W13: =C13 -> CRASOME Polyester Kitchen Apron for Men Women Chef Cooking Restaurants gardening workshop barbers With Pockets and Adjustable Strap (Blue) | X13: =SUMIFS('Transit Shipment'!$B$10:$B$1048462,'Transit Shipment'!$A$10:$A$1048462,B13,'Transit Shipment'!$C$10:$C$1048462,AA13) -> 0 | Y13: =IF(SUMIFS(DIH!$S$2:$S833,DIH!$D$2:$D833,B13,DIH!$U$2:$U833,AA13)>0,SUMIFS(DIH!$S$2:$S833,DIH!$D$2:$D833,B13,DIH!$U$2:$U833,AA13),0) -> 3 | Z13: =SUM(X13:Y13) -> 3 | AA13: AMD2 | AB13: =IF(ISNA(VLOOKUP($B13,'Business Report'!$D$2:$J$202,2,0)),"",VLOOKUP($B13,'Business Report'!$D$2:$J$202,2,0)) -> 15 | AC13: =SUMIFS(AFS!$P$2:$P$6260,AFS!$N$2:$N$6260,B13,AFS!$AT$2:$AT$6260,AA13) -> 1 | AD13: =CEILING(AC13/$W$2*$X$2,1)-sum(X13:Y13) -> -1 | AF13: =IF(ISNUMBER(AD13),IF(AD13<=0,"",IF(F13="","",E13*$AC$2+IF(F13>0,$AC$2,0)))) | AI13: =IF(ISNUMBER(AG13),IF(AG13<=0,"",IF(I13="","",H13*$AC$2+IF(I13>0,$AC$2,0)))) -> FALSE
A14: APR- Dark Blue | B14: Apron_Blue | C14: CRASOME Polyester Kitchen Apron for Men Women Chef Cooking Restaurants gardening workshop barbers With Pockets and Adjustable Strap (Blue) | D14: Apron | E14: =IF(ISNUMBER(AD14),IF(AD14>=0,IF(AD14=0,1,INT(AD14/$AC$2)),""),"") -> 8 | F14: =IF(E14="","",IF(AD14=0,0,AD14/$AC$2-E14)) -> 0 | G14: =IF(ISERROR(SEARCH("Apron",D14)),AF14,"") | I14: =IF(ISNUMBER($AF14),1*$AF14,"") -> 16 | P14: {=XLOOKUP(B14,Weight!B:B,Weight!D:D,"#N/A",0)} -> 140 | Q14: =IF(AF14="","",AF14*P14) -> 2240 | S14: 392620 | T14: 12 | U14: 60 | X14: =SUMIFS('Transit Shipment'!$B$10:$B$1048462,'Transit Shipment'!$A$10:$A$1048462,B14,'Transit Shipment'!$C$10:$C$1048462,AA14) -> 0 | Y14: =IF(SUMIFS(DIH!$S$2:$S833,DIH!$D$2:$D833,B14,DIH!$U$2:$U833,AA14)>0,SUMIFS(DIH!$S$2:$S833,DIH!$D$2:$D833,B14,DIH!$U$2:$U833,AA14),0) -> 0 | Z14: =SUM(X14:Y14) -> 0 | AA14: BLR8 | AB14: =IF(ISNA(VLOOKUP($B14,'Business Report'!$D$2:$J$202,2,0)),"",VLOOKUP($B14,'Business Report'!$D$2:$J$202,2,0)) -> 15 | AC14: =SUMIFS(AFS!$P$2:$P$6260,AFS!$N$2:$N$6260,B14,AFS!$AT$2:$AT$6260,AA14) -> 12 | AD14: =CEILING(AC14/$W$2*$X$2,1)-sum(X14:Y14) -> 16 | AF14: =IF(ISNUMBER(AD14),IF(AD14<=0,"",IF(F14="","",E14*$AC$2+IF(F14>0,$AC$2,0)))) -> 16 | AI14: =IF(ISNUMBER(AG14),IF(AG14<=0,"",IF(I14="","",H14*$AC$2+IF(I14>0,$AC$2,0)))) -> FALSE
A15: APR- Dark Blue | B15: Apron_Blue | C15: CRASOME Polyester Kitchen Apron for Men Women Chef Cooking Restaurants gardening workshop barbers With Pockets and Adjustable Strap (Blue) | D15: Apron | E15: =IF(ISNUMBER(AD15),IF(AD15>=0,IF(AD15=0,1,INT(AD15/$AC$2)),""),"") -> 2 | F15: =IF(E15="","",IF(AD15=0,0,AD15/$AC$2-E15)) -> 0.5 | G15: =IF(ISERROR(SEARCH("Apron",D15)),AF15,"") | I15: =IF(ISNUMBER($AF15),1*$AF15,"") -> 6 | P15: {=XLOOKUP(B15,Weight!B:B,Weight!D:D,"#N/A",0)} -> 140 | Q15: =IF(AF15="","",AF15*P15) -> 840 | S15: 392620 | T15: 12 | U15: 60 | X15: =SUMIFS('Transit Shipment'!$B$10:$B$1048462,'Transit Shipment'!$A$10:$A$1048462,B15,'Transit Shipment'!$C$10:$C$1048462,AA15) -> 0 | Y15: =IF(SUMIFS(DIH!$S$2:$S833,DIH!$D$2:$D833,B15,DIH!$U$2:$U833,AA15)>0,SUMIFS(DIH!$S$2:$S833,DIH!$D$2:$D833,B15,DIH!$U$2:$U833,AA15),0) -> 2 | Z15: =SUM(X15:Y15) -> 2 | AA15: BLR7 | AB15: =IF(ISNA(VLOOKUP($B15,'Business Report'!$D$2:$J$202,2,0)),"",VLOOKUP($B15,'Business Report'!$D$2:$J$202,2,0)) -> 15 | AC15: =SUMIFS(AFS!$P$2:$P$6260,AFS!$N$2:$N$6260,B15,AFS!$AT$2:$AT$6260,AA15) -> 5 | AD15: =CEILING(AC15/$W$2*$X$2,1)-sum(X15:Y15) -> 5 | AF15: =IF(ISNUMBER(AD15),IF(AD15<=0,"",IF(F15="","",E15*$AC$2+IF(F15>0,$AC$2,0)))) -> 6 | AI15: =IF(ISNUMBER(AG15),IF(AG15<=0,"",IF(I15="","",H15*$AC$2+IF(I15>0,$AC$2,0)))) -> FALSE
A16: APR- Dark Blue | B16: Apron_Blue | C16: CRASOME Polyester Kitchen Apron for Men Women Chef Cooking Restaurants gardening workshop barbers With Pockets and Adjustable Strap (Blue) | D16: Apron | E16: =IF(ISNUMBER(AD16),IF(AD16>=0,IF(AD16=0,1,INT(AD16/$AC$2)),""),"") -> 1 | F16: =IF(E16="","",IF(AD16=0,0,AD16/$AC$2-E16)) -> 0.5 | G16: =IF(ISERROR(SEARCH("Apron",D16)),AF16,"") | I16: =IF(ISNUMBER($AF16),1*$AF16,"") -> 4 | P16: {=XLOOKUP(B16,Weight!B:B,Weight!D:D,"#N/A",0)} -> 140 | Q16: =IF(AF16="","",AF16*P16) -> 560 | S16: 392620 | T16: 12 | U16: 60 | X16: =SUMIFS('Transit Shipment'!$B$10:$B$1048462,'Transit Shipment'!$A$10:$A$1048462,B16,'Transit Shipment'!$C$10:$C$1048462,AA16) -> 0 | Y16: =IF(SUMIFS(DIH!$S$2:$S833,DIH!$D$2:$D833,B16,DIH!$U$2:$U833,AA16)>0,SUMIFS(DIH!$S$2:$S833,DIH!$D$2:$D833,B16,DIH!$U$2:$U833,AA16),0) -> 1 | Z16: =SUM(X16:Y16) -> 1 | AA16: CJB1 | AB16: =IF(ISNA(VLOOKUP($B16,'Business Report'!$D$2:$J$202,2,0)),"",VLOOKUP($B16,'Business Report'!$D$2:$J$202,2,0)) -> 15 | AC16: =SUMIFS(AFS!$P$2:$P$6260,AFS!$N$2:$N$6260,B16,AFS!$AT$2:$AT$6260,AA16) -> 3 | AD16: =CEILING(AC16/$W$2*$X$2,1)-sum(X16:Y16) -> 3 | AF16: =IF(ISNUMBER(AD16),IF(AD16<=0,"",IF(F16="","",E16*$AC$2+IF(F16>0,$AC$2,0)))) -> 4 | AI16: =IF(ISNUMBER(AG16),IF(AG16<=0,"",IF(I16="","",H16*$AC$2+IF(I16>0,$AC$2,0)))) -> FALSE
A17: APR- Dark Blue | B17: Apron_Blue | C17: CRASOME Polyester Kitchen Apron for Men Women Chef Cooking Restaurants gardening workshop barbers With Pockets and Adjustable Strap (Blue) | D17: Apron | E17: =IF(ISNUMBER(AD17),IF(AD17>=0,IF(AD17=0,1,INT(AD17/$AC$2)),""),"") -> 4 | F17: =IF(E17="","",IF(AD17=0,0,AD17/$AC$2-E17)) -> 0.5 | G17: =IF(ISERROR(SEARCH("Apron",D17)),AF17,"") | I17: =IF(ISNUMBER($AF17),1*$AF17,"") -> 10 | P17: {=XLOOKUP(B17,Weight!B:B,Weight!D:D,"#N/A",0)} -> 140 | Q17: =IF(AF17="","",AF17*P17) -> 1400 | S17: 392620 | T17: 12 | U17: 60 | X17: =SUMIFS('Transit Shipment'!$B$10:$B$1048462,'Transit Shipment'!$A$10:$A$1048462,B17,'Transit Shipment'!$C$10:$C$1048462,AA17) -> 0 | Y17: =IF(SUMIFS(DIH!$S$2:$S833,DIH!$D$2:$D833,B17,DIH!$U$2:$U833,AA17)>0,SUMIFS(DIH!$S$2:$S833,DIH!$D$2:$D833,B17,DIH!$U$2:$U833,AA17),0) -> 1 | Z17: =SUM(X17:Y17) -> 1 | AA17: MAA4 | AB17: =IF(ISNA(VLOOKUP($B17,'Business Report'!$D$2:$J$202,2,0)),"",VLOOKUP($B17,'Business Report'!$D$2:$J$202,2,0)) -> 15 | AC17: =SUMIFS(AFS!$P$2:$P$6260,AFS!$N$2:$N$6260,B17,AFS!$AT$2:$AT$6260,AA17) -> 7 | AD17: =CEILING(AC17/$W$2*$X$2,1)-sum(X17:Y17) -> 9 | AF17: =IF(ISNUMBER(AD17),IF(AD17<=0,"",IF(F17="","",E17*$AC$2+IF(F17>0,$AC$2,0)))) -> 10 | AI17: =IF(ISNUMBER(AG17),IF(AG17<=0,"",IF(I17="","",H17*$AC$2+IF(I17>0,$AC$2,0)))) -> FALSE
A18: APR- Dark Blue | B18: Apron_Blue | C18: CRASOME Polyester Kitchen Apron for Men Women Chef Cooking Restaurants gardening workshop barbers With Pockets and Adjustable Strap (Blue) | D18: Apron | E18: =IF(ISNUMBER(AD18),IF(AD18>=0,IF(AD18=0,1,INT(AD18/$AC$2)),""),"") -> 1 | F18: =IF(E18="","",IF(AD18=0,0,AD18/$AC$2-E18)) -> 0 | G18: =IF(ISERROR(SEARCH("Apron",D18)),AF18,"") | I18: =IF(ISNUMBER($AF18),1*$AF18,"") | P18: {=XLOOKUP(B18,Weight!B:B,Weight!D:D,"#N/A",0)} -> 140 | Q18: =IF(AF18="","",AF18*P18) | S18: 392620 | T18: 12 | U18: 60 | X18: =SUMIFS('Transit Shipment'!$B$10:$B$1048462,'Transit Shipment'!$A$10:$A$1048462,B18,'Transit Shipment'!$C$10:$C$1048462,AA18) -> 0 | Y18: =IF(SUMIFS(DIH!$S$2:$S833,DIH!$D$2:$D833,B18,DIH!$U$2:$U833,AA18)>0,SUMIFS(DIH!$S$2:$S833,DIH!$D$2:$D833,B18,DIH!$U$2:$U833,AA18),0) -> 2 | Z18: =SUM(X18:Y18) -> 2 | AA18: DEL4 | AB18: =IF(ISNA(VLOOKUP($B18,'Business Report'!$D$2:$J$202,2,0)),"",VLOOKUP($B18,'Business Report'!$D$2:$J$202,2,0)) -> 15 | AC18: =SUMIFS(AFS!$P$2:$P$6260,AFS!$N$2:$N$6260,B18,AFS!$AT$2:$AT$6260,AA18) -> 1 | AD18: =CEILING(AC18/$W$2*$X$2,1)-sum(X18:Y18) -> 0 | AF18: =IF(ISNUMBER(AD18),IF(AD18<=0,"",IF(F18="","",E18*$AC$2+IF(F18>0,$AC$2,0)))) | AI18: =IF(ISNUMBER(AG18),IF(AG18<=0,"",IF(I18="","",H18*$AC$2+IF(I18>0,$AC$2,0)))) -> FALSE
A19: APR- Dark Blue | B19: Apron_Blue | C19: CRASOME Polyester Kitchen Apron for Men Women Chef Cooking Restaurants gardening workshop barbers With Pockets and Adjustable Strap (Blue) | D19: Apron | E19: =IF(ISNUMBER(AD19),IF(AD19>=0,IF(AD19=0,1,INT(AD19/$AC$2)),""),"") -> 3 | F19: =IF(E19="","",IF(AD19=0,0,AD19/$AC$2-E19)) -> 0 | G19: =IF(ISERROR(SEARCH("Apron",D19)),AF19,"") | I19: =IF(ISNUMBER($AF19),1*$AF19,"") -> 6 | P19: {=XLOOKUP(B19,Weight!B:B,Weight!D:D,"#N/A",0)} -> 140 | Q19: =IF(AF19="","",AF19*P19) -> 840 | S19: 392620 | T19: 12 | U19: 60 | X19: =SUMIFS('Transit Shipment'!$B$10:$B$1048462,'Transit Shipment'!$A$10:$A$1048462,B19,'Transit Shipment'!$C$10:$C$1048462,AA19) -> 0 | Y19: =IF(SUMIFS(DIH!$S$2:$S833,DIH!$D$2:$D833,B19,DIH!$U$2:$U833,AA19)>0,SUMIFS(DIH!$S$2:$S833,DIH!$D$2:$D833,B19,DIH!$U$2:$U833,AA19),0) -> 2 | Z19: =SUM(X19:Y19) -> 2 | AA19: DEL5 | AB19: =IF(ISNA(VLOOKUP($B19,'Business Report'!$D$2:$J$202,2,0)),"",VLOOKUP($B19,'Business Report'!$D$2:$J$202,2,0)) -> 15 | AC19: =SUMIFS(AFS!$P$2:$P$6260,AFS!$N$2:$N$6260,B19,AFS!$AT$2:$AT$6260,AA19) -> 6 | AD19: =CEILING(AC19/$W$2*$X$2,1)-sum(X19:Y19) -> 6 | AF19: =IF(ISNUMBER(AD19),IF(AD19<=0,"",IF(F19="","",E19*$AC$2+IF(F19>0,$AC$2,0)))) -> 6 | AI19: =IF(ISNUMBER(AG19),IF(AG19<=0,"",IF(I19="","",H19*$AC$2+IF(I19>0,$AC$2,0)))) -> FALSE
A20: APR- Dark Blue | B20: Apron_Blue | C20: CRASOME Polyester Kitchen Apron for Men Women Chef Cooking Restaurants gardening workshop barbers With Pockets and Adjustable Strap (Blue) | D20: Apron | E20: =IF(ISNUMBER(AD20),IF(AD20>=0,IF(AD20=0,1,INT(AD20/$AC$2)),""),"") -> 1 | F20: =IF(E20="","",IF(AD20=0,0,AD20/$AC$2-E20)) -> 0 | G20: =IF(ISERROR(SEARCH("Apron",D20)),AF20,"") | I20: =IF(ISNUMBER($AF20),1*$AF20,"") | P20: {=XLOOKUP(B20,Weight!B:B,Weight!D:D,"#N/A",0)} -> 140 | Q20: =IF(AF20="","",AF20*P20) | S20: 392620 | T20: 12 | U20: 60 | X20: =SUMIFS('Transit Shipment'!$B$10:$B$1048462,'Transit Shipment'!$A$10:$A$1048462,B20,'Transit Shipment'!$C$10:$C$1048462,AA20) -> 0 | Y20: =IF(SUMIFS(DIH!$S$2:$S833,DIH!$D$2:$D833,B20,DIH!$U$2:$U833,AA20)>0,SUMIFS(DIH!$S$2:$S833,DIH!$D$2:$D833,B20,DIH!$U$2:$U833,AA20),0) -> 7 | Z20: =SUM(X20:Y20) -> 7 | AA20: BOM5 | AB20: =IF(ISNA(VLOOKUP($B20,'Business Report'!$D$2:$J$202,2,0)),"",VLOOKUP($B20,'Business Report'!$D$2:$J$202,2,0)) -> 15 | AC20: =SUMIFS(AFS!$P$2:$P$6260,AFS!$N$2:$N$6260,B20,AFS!$AT$2:$AT$6260,AA20) -> 5 | AD20: =CEILING(AC20/$W$2*$X$2,1)-sum(X20:Y20) -> 0 | AF20: =IF(ISNUMBER(AD20),IF(AD20<=0,"",IF(F20="","",E20*$AC$2+IF(F20>0,$AC$2,0)))) | AI20: =IF(ISNUMBER(AG20),IF(AG20<=0,"",IF(I20="","",H20*$AC$2+IF(I20>0,$AC$2,0)))) -> FALSE
A21: APR- Dark Blue | B21: Apron_Blue | C21: CRASOME Polyester Kitchen Apron for Men Women Chef Cooking Restaurants gardening workshop barbers With Pockets and Adjustable Strap (Blue) | D21: Apron | E21: =IF(ISNUMBER(AD21),IF(AD21>=0,IF(AD21=0,1,INT(AD21/$AC$2)),""),"") -> 1 | F21: =IF(E21="","",IF(AD21=0,0,AD21/$AC$2-E21)) -> 0 | G21: =IF(ISERROR(SEARCH("Apron",D21)),AF21,"") | I21: =IF(ISNUMBER($AF21),1*$AF21,"") | P21: {=XLOOKUP(B21,Weight!B:B,Weight!D:D,"#N/A",0)} -> 140 | Q21: =IF(AF21="","",AF21*P21) | S21: 392620 | T21: 12 | U21: 60 | X21: =SUMIFS('Transit Shipment'!$B$10:$B$1048462,'Transit Shipment'!$A$10:$A$1048462,B21,'Transit Shipment'!$C$10:$C$1048462,AA21) -> 0 | Y21: =IF(SUMIFS(DIH!$S$2:$S833,DIH!$D$2:$D833,B21,DIH!$U$2:$U833,AA21)>0,SUMIFS(DIH!$S$2:$S833,DIH!$D$2:$D833,B21,DIH!$U$2:$U833,AA21),0) -> 0 | Z21: =SUM(X21:Y21) -> 0 | AA21: BOM7 | AB21: =IF(ISNA(VLOOKUP($B21,'Business Report'!$D$2:$J$202,2,0)),"",VLOOKUP($B21,'Business Report'!$D$2:$J$202,2,0)) -> 15 | AC21: =SUMIFS(AFS!$P$2:$P$6260,AFS!$N$2:$N$6260,B21,AFS!$AT$2:$AT$6260,AA21) -> 0 | AD21: =CEILING(AC21/$W$2*$X$2,1)-sum(X21:Y21) -> 0 | AE21: =SUM(AD13:AD21) -> 38 | AF21: =IF(ISNUMBER(AD21),IF(AD21<=0,"",IF(F21="","",E21*$AC$2+IF(F21>0,$AC$2,0)))) | AI21: =IF(ISNUMBER(AG21),IF(AG21<=0,"",IF(I21="","",H21*$AC$2+IF(I21>0,$AC$2,0)))) -> FALSE
A22: APR- Brown | B22: Apron_Brown | C22: CRASOME Polyester Kitchen Apron for Men Women Chef Cooking Restaurants gardening workshop, barbers With Pockets and Adjustable Strap ( Brown ) | D22: Apron | E22: =IF(ISNUMBER(AD22),IF(AD22>=0,IF(AD22=0,1,INT(AD22/$AC$2)),""),"") | F22: =IF(E22="","",IF(AD22=0,0,AD22/$AC$2-E22)) | G22: =IF(ISERROR(SEARCH("Apron",D22)),AF22,"") | J22: =IF(ISNUMBER($AF22),1*$AF22,"") | P22: {=XLOOKUP(B22,Weight!B:B,Weight!D:D,"#N/A",0)} -> 140 | Q22: =IF(AF22="","",AF22*P22) | S22: 392620 | T22: 12 | U22: 60 | V22: =B22 -> Apron_Brown | W22: =C22 -> CRASOME Polyester Kitchen Apron for Men Women Chef Cooking Restaurants gardening workshop, barbers With Pockets and Adjustable Strap ( Brown ) | X22: =SUMIFS('Transit Shipment'!$B$10:$B$1048462,'Transit Shipment'!$A$10:$A$1048462,B22,'Transit Shipment'!$C$10:$C$1048462,AA22) -> 0 | Y22: =IF(SUMIFS(DIH!$S$2:$S833,DIH!$D$2:$D833,B22,DIH!$U$2:$U833,AA22)>0,SUMIFS(DIH!$S$2:$S833,DIH!$D$2:$D833,B22,DIH!$U$2:$U833,AA22),0) -> 5 | Z22: =SUM(X22:Y22) -> 5 | AA22: AMD2 | AB22: =IF(ISNA(VLOOKUP($B22,'Business Report'!$D$2:$J$202,2,0)),"",VLOOKUP($B22,'Business Report'!$D$2:$J$202,2,0)) -> 33 | AC22: =SUMIFS(AFS!$P$2:$P$6260,AFS!$N$2:$N$6260,B22,AFS!$AT$2:$AT$6260,AA22) -> 0 | AD22: =CEILING(AC22/$W$2*$X$2,1)-sum(X22:Y22) -> -5 | AF22: =IF(ISNUMBER(AD22),IF(AD22<=0,"",IF(F22="","",E22*$AC$2+IF(F22>0,$AC$2,0))))
A23: APR- Brown | B23: Apron_Brown | C23: CRASOME Polyester Kitchen Apron for Men Women Chef Cooking Restaurants gardening workshop, barbers With Pockets and Adjustable Strap ( Brown ) | D23: Apron | E23: =IF(ISNUMBER(AD23),IF(AD23>=0,IF(AD23=0,1,INT(AD23/$AC$2)),""),"") | F23: =IF(E23="","",IF(AD23=0,0,AD23/$AC$2-E23)) | G23: =IF(ISERROR(SEARCH("Apron",D23)),AF23,"") | J23: =IF(ISNUMBER($AF23),1*$AF23,"") | P23: {=XLOOKUP(B23,Weight!B:B,Weight!D:D,"#N/A",0)} -> 140 | Q23: =IF(AF23="","",AF23*P23) | S23: 392620 | T23: 12 | U23: 60 | X23: =SUMIFS('Transit Shipment'!$B$10:$B$1048462,'Transit Shipment'!$A$10:$A$1048462,B23,'Transit Shipment'!$C$10:$C$1048462,AA23) -> 0 | Y23: =IF(SUMIFS(DIH!$S$2:$S833,DIH!$D$2:$D833,B23,DIH!$U$2:$U833,AA23)>0,SUMIFS(DIH!$S$2:$S833,DIH!$D$2:$D833,B23,DIH!$U$2:$U833,AA23),0) -> 21 | Z23: =SUM(X23:Y23) -> 21 | AA23: BLR8 | AB23: =IF(ISNA(VLOOKUP($B23,'Business Report'!$D$2:$J$202,2,0)),"",VLOOKUP($B23,'Business Report'!$D$2:$J$202,2,0)) -> 33 | AC23: =SUMIFS(AFS!$P$2:$P$6260,AFS!$N$2:$N$6260,B23,AFS!$AT$2:$AT$6260,AA23) -> 4 | AD23: =CEILING(AC23/$W$2*$X$2,1)-sum(X23:Y23) -> -15 | AF23: =IF(ISNUMBER(AD23),IF(AD23<=0,"",IF(F23="","",E23*$AC$2+IF(F23>0,$AC$2,0))))
A24: APR- Brown | B24: Apron_Brown | C24: CRASOME Polyester Kitchen Apron for Men Women Chef Cooking Restaurants gardening workshop, barbers With Pockets and Adjustable Strap ( Brown ) | D24: Apron | E24: =IF(ISNUMBER(AD24),IF(AD24>=0,IF(AD24=0,1,INT(AD24/$AC$2)),""),"") -> 2 | F24: =IF(E24="","",IF(AD24=0,0,AD24/$AC$2-E24)) -> 0.5 | G24: =IF(ISERROR(SEARCH("Apron",D24)),AF24,"") | J24: =IF(ISNUMBER($AF24),1*$AF24,"") -> 6 | P24: {=XLOOKUP(B24,Weight!B:B,Weight!D:D,"#N/A",0)} -> 140 | Q24: =IF(AF24="","",AF24*P24) -> 840 | S24: 392620 | T24: 12 | U24: 60 | X24: =SUMIFS('Transit Shipment'!$B$10:$B$1048462,'Transit Shipment'!$A$10:$A$1048462,B24,'Transit Shipment'!$C$10:$C$1048462,AA24) -> 0 | Y24: =IF(SUMIFS(DIH!$S$2:$S833,DIH!$D$2:$D833,B24,DIH!$U$2:$U833,AA24)>0,SUMIFS(DIH!$S$2:$S833,DIH!$D$2:$D833,B24,DIH!$U$2:$U833,AA24),0) -> 7 | Z24: =SUM(X24:Y24) -> 7 | AA24: BLR7 | AB24: =IF(ISNA(VLOOKUP($B24,'Business Report'!$D$2:$J$202,2,0)),"",VLOOKUP($B24,'Business Report'!$D$2:$J$202,2,0)) -> 33 | AC24: =SUMIFS(AFS!$P$2:$P$6260,AFS!$N$2:$N$6260,B24,AFS!$AT$2:$AT$6260,AA24) -> 9 | AD24: =CEILING(AC24/$W$2*$X$2,1)-sum(X24:Y24) -> 5 | AF24: =IF(ISNUMBER(AD24),IF(AD24<=0,"",IF(F24="","",E24*$AC$2+IF(F24>0,$AC$2,0)))) -> 6
A25: APR- Brown | B25: Apron_Brown | C25: CRASOME Polyester Kitchen Apron for Men Women Chef Cooking Restaurants gardening workshop, barbers With Pockets and Adjustable Strap ( Brown ) | D25: Apron | E25: =IF(ISNUMBER(AD25),IF(AD25>=0,IF(AD25=0,1,INT(AD25/$AC$2)),""),"") | F25: =IF(E25="","",IF(AD25=0,0,AD25/$AC$2-E25)) | G25: =IF(ISERROR(SEARCH("Apron",D25)),AF25,"") | J25: =IF(ISNUMBER($AF25),1*$AF25,"") | P25: {=XLOOKUP(B25,Weight!B:B,Weight!D:D,"#N/A",0)} -> 140 | Q25: =IF(AF25="","",AF25*P25) | S25: 392620 | T25: 12 | U25: 60 | X25: =SUMIFS('Transit Shipment'!$B$10:$B$1048462,'Transit Shipment'!$A$10:$A$1048462,B25,'Transit Shipment'!$C$10:$C$1048462,AA25) -> 0 | Y25: =IF(SUMIFS(DIH!$S$2:$S833,DIH!$D$2:$D833,B25,DIH!$U$2:$U833,AA25)>0,SUMIFS(DIH!$S$2:$S833,DIH!$D$2:$D833,B25,DIH!$U$2:$U833,AA25),0) -> 3 | Z25: =SUM(X25:Y25) -> 3 | AA25: CJB1 | AB25: =IF(ISNA(VLOOKUP($B25,'Business Report'!$D$2:$J$202,2,0)),"",VLOOKUP($B25,'Business Report'!$D$2:$J$202,2,0)) -> 33 | AC25: =SUMIFS(AFS!$P$2:$P$6260,AFS!$N$2:$N$6260,B25,AFS!$AT$2:$AT$6260,AA25) -> 1 | AD25: =CEILING(AC25/$W$2*$X$2,1)-sum(X25:Y25) -> -1 | AF25: =IF(ISNUMBER(AD25),IF(AD25<=0,"",IF(F25="","",E25*$AC$2+IF(F25>0,$AC$2,0))))
A26: APR- Brown | B26: Apron_Brown | C26: CRASOME Polyester Kitchen Apron for Men Women Chef Cooking Restaurants gardening workshop, barbers With Pockets and Adjustable Strap ( Brown ) | D26: Apron | E26: =IF(ISNUMBER(AD26),IF(AD26>=0,IF(AD26=0,1,INT(AD26/$AC$2)),""),"") | F26: =IF(E26="","",IF(AD26=0,0,AD26/$AC$2-E26)) | G26: =IF(ISERROR(SEARCH("Apron",D26)),AF26,"") | J26: =IF(ISNUMBER($AF26),1*$AF26,"") | P26: {=XLOOKUP(B26,Weight!B:B,Weight!D:D,"#N/A",0)} -> 140 | Q26: =IF(AF26="","",AF26*P26) | S26: 392620 | T26: 12 | U26: 60 | X26: =SUMIFS('Transit Shipment'!$B$10:$B$1048462,'Transit Shipment'!$A$10:$A$1048462,B26,'Transit Shipment'!$C$10:$C$1048462,AA26) -> 0 | Y26: =IF(SUMIFS(DIH!$S$2:$S833,DIH!$D$2:$D833,B26,DIH!$U$2:$U833,AA26)>0,SUMIFS(DIH!$S$2:$S833,DIH!$D$2:$D833,B26,DIH!$U$2:$U833,AA26),0) -> 17 | Z26: =SUM(X26:Y26) -> 17 | AA26: MAA4 | AB26: =IF(ISNA(VLOOKUP($B26,'Business Report'!$D$2:$J$202,2,0)),"",VLOOKUP($B26,'Business Report'!$D$2:$J$202,2,0)) -> 33 | AC26: =SUMIFS(AFS!$P$2:$P$6260,AFS!$N$2:$N$6260,B26,AFS!$AT$2:$AT$6260,AA26) -> 8 | AD26: =CEILING(AC26/$W$2*$X$2,1)-sum(X26:Y26) -> -6 | AF26: =IF(ISNUMBER(AD26),IF(AD26<=0,"",IF(F26="","",E26*$AC$2+IF(F26>0,$AC$2,0))))
A27: APR- Brown | B27: Apron_Brown | C27: CRASOME Polyester Kitchen Apron for Men Women Chef Cooking Restaurants gardening workshop, barbers With Pockets and Adjustable Strap ( Brown ) | D27: Apron | E27: =IF(ISNUMBER(AD27),IF(AD27>=0,IF(AD27=0,1,INT(AD27/$AC$2)),""),"") -> 1 | F27: =IF(E27="","",IF(AD27=0,0,AD27/$AC$2-E27)) -> 0.5 | G27: =IF(ISERROR(SEARCH("Apron",D27)),AF27,"") | J27: =IF(ISNUMBER($AF27),1*$AF27,"") -> 4 | P27: {=XLOOKUP(B27,Weight!B:B,Weight!D:D,"#N/A",0)} -> 140 | Q27: =IF(AF27="","",AF27*P27) -> 560 | S27: 392620 | T27: 12 | U27: 60 | X27: =SUMIFS('Transit Shipment'!$B$10:$B$1048462,'Transit Shipment'!$A$10:$A$1048462,B27,'Transit Shipment'!$C$10:$C$1048462,AA27) -> 0 | Y27: =IF(SUMIFS(DIH!$S$2:$S833,DIH!$D$2:$D833,B27,DIH!$U$2:$U833,AA27)>0,SUMIFS(DIH!$S$2:$S833,DIH!$D$2:$D833,B27,DIH!$U$2:$U833,AA27),0) -> 8 | Z27: =SUM(X27:Y27) -> 8 | AA27: DEL4 | AB27: =IF(ISNA(VLOOKUP($B27,'Business Report'!$D$2:$J$202,2,0)),"",VLOOKUP($B27,'Business Report'!$D$2:$J$202,2,0)) -> 33 | AC27: =SUMIFS(AFS!$P$2:$P$6260,AFS!$N$2:$N$6260,B27,AFS!$AT$2:$AT$6260,AA27) -> 8 | AD27: =CEILING(AC27/$W$2*$X$2,1)-sum(X27:Y27) -> 3 | AF27: =IF(ISNUMBER(AD27),IF(AD27<=0,"",IF(F27="","",E27*$AC$2+IF(F27>0,$AC$2,0)))) -> 4
A28: APR- Brown | B28: Apron_Brown | C28: CRASOME Polyester Kitchen Apron for Men Women Chef Cooking Restaurants gardening workshop, barbers With Pockets and Adjustable Strap ( Brown ) | D28: Apron | E28: =IF(ISNUMBER(AD28),IF(AD28>=0,IF(AD28=0,1,INT(AD28/$AC$2)),""),"") -> 1 | F28: =IF(E28="","",IF(AD28=0,0,AD28/$AC$2-E28)) -> 0.5 | G28: =IF(ISERROR(SEARCH("Apron",D28)),AF28,"") | J28: =IF(ISNUMBER($AF28),1*$AF28,"") -> 4 | P28: {=XLOOKUP(B28,Weight!B:B,Weight!D:D,"#N/A",0)} -> 140 | Q28: =IF(AF28="","",AF28*P28) -> 560 | S28: 392620 | T28: 12 | U28: 60 | X28: =SUMIFS('Transit Shipment'!$B$10:$B$1048462,'Transit Shipment'!$A$10:$A$1048462,B28,'Transit Shipment'!$C$10:$C$1048462,AA28) -> 0 | Y28: =IF(SUMIFS(DIH!$S$2:$S833,DIH!$D$2:$D833,B28,DIH!$U$2:$U833,AA28)>0,SUMIFS(DIH!$S$2:$S833,DIH!$D$2:$D833,B28,DIH!$U$2:$U833,AA28),0) -> 8 | Z28: =SUM(X28:Y28) -> 8 | AA28: DEL5 | AB28: =IF(ISNA(VLOOKUP($B28,'Business Report'!$D$2:$J$202,2,0)),"",VLOOKUP($B28,'Business Report'!$D$2:$J$202,2,0)) -> 33 | AC28: =SUMIFS(AFS!$P$2:$P$6260,AFS!$N$2:$N$6260,B28,AFS!$AT$2:$AT$6260,AA28) -> 8 | AD28: =CEILING(AC28/$W$2*$X$2,1)-sum(X28:Y28) -> 3 | AF28: =IF(ISNUMBER(AD28),IF(AD28<=0,"",IF(F28="","",E28*$AC$2+IF(F28>0,$AC$2,0)))) -> 4
A29: APR- Brown | B29: Apron_Brown | C29: CRASOME Polyester Kitchen Apron for Men Women Chef Cooking Restaurants gardening workshop, barbers With Pockets and Adjustable Strap ( Brown ) | D29: Apron | E29: =IF(ISNUMBER(AD29),IF(AD29>=0,IF(AD29=0,1,INT(AD29/$AC$2)),""),"") | F29: =IF(E29="","",IF(AD29=0,0,AD29/$AC$2-E29)) | G29: =IF(ISERROR(SEARCH("Apron",D29)),AF29,"") | J29: =IF(ISNUMBER($AF29),1*$AF29,"") | P29: {=XLOOKUP(B29,Weight!B:B,Weight!D:D,"#N/A",0)} -> 140 | Q29: =IF(AF29="","",AF29*P29) | S29: 392620 | T29: 12 | U29: 60 | X29: =SUMIFS('Transit Shipment'!$B$10:$B$1048462,'Transit Shipment'!$A$10:$A$1048462,B29,'Transit Shipment'!$C$10:$C$1048462,AA29) -> 0 | Y29: =IF(SUMIFS(DIH!$S$2:$S833,DIH!$D$2:$D833,B29,DIH!$U$2:$U833,AA29)>0,SUMIFS(DIH!$S$2:$S833,DIH!$D$2:$D833,B29,DIH!$U$2:$U833,AA29),0) -> 10 | Z29: =SUM(X29:Y29) -> 10 | AA29: BOM5 | AB29: =IF(ISNA(VLOOKUP($B29,'Business Report'!$D$2:$J$202,2,0)),"",VLOOKUP($B29,'Business Report'!$D$2:$J$202,2,0)) -> 33 | AC29: =SUMIFS(AFS!$P$2:$P$6260,AFS!$N$2:$N$6260,B29,AFS!$AT$2:$AT$6260,AA29) -> 4 | AD29: =CEILING(AC29/$W$2*$X$2,1)-sum(X29:Y29) -> -4 | AF29: =IF(ISNUMBER(AD29),IF(AD29<=0,"",IF(F29="","",E29*$AC$2+IF(F29>0,$AC$2,0))))
A30: APR- Brown | B30: Apron_Brown | C30: CRASOME Polyester Kitchen Apron for Men Women Chef Cooking Restaurants gardening workshop, barbers With Pockets and Adjustable Strap ( Brown ) | D30: Apron | E30: =IF(ISNUMBER(AD30),IF(AD30>=0,IF(AD30=0,1,INT(AD30/$AC$2)),""),"") -> 1 | F30: =IF(E30="","",IF(AD30=0,0,AD30/$AC$2-E30)) -> 0 | G30: =IF(ISERROR(SEARCH("Apron",D30)),AF30,"") | J30: =IF(ISNUMBER($AF30),1*$AF30,"") -> 2 | P30: {=XLOOKUP(B30,Weight!B:B,Weight!D:D,"#N/A",0)} -> 140 | Q30: =IF(AF30="","",AF30*P30) -> 280 | S30: 392620 | T30: 12 | U30: 60 | X30: =SUMIFS('Transit Shipment'!$B$10:$B$1048462,'Transit Shipment'!$A$10:$A$1048462,B30,'Transit Shipment'!$C$10:$C$1048462,AA30) -> 0 | Y30: =IF(SUMIFS(DIH!$S$2:$S833,DIH!$D$2:$D833,B30,DIH!$U$2:$U833,AA30)>0,SUMIFS(DIH!$S$2:$S833,DIH!$D$2:$D833,B30,DIH!$U$2:$U833,AA30),0) -> 0 | Z30: =SUM(X30:Y30) -> 0 | AA30: BOM7 | AB30: =IF(ISNA(VLOOKUP($B30,'Business Report'!$D$2:$J$202,2,0)),"",VLOOKUP($B30,'Business Report'!$D$2:$J$202,2,0)) -> 33 | AC30: =SUMIFS(AFS!$P$2:$P$6260,AFS!$N$2:$N$6260,B30,AFS!$AT$2:$AT$6260,AA30) -> 1 | AD30: =CEILING(AC30/$W$2*$X$2,1)-sum(X30:Y30) -> 2 | AE30: =SUM(AD22:AD30) -> -18 | AF30: =IF(ISNUMBER(AD30),IF(AD30<=0,"",IF(F30="","",E30*$AC$2+IF(F30>0,$AC$2,0)))) -> 2
A31: APR- Grey | B31: Apron_Grey | C31: CRASOME Polyester Kitchen Apron for Men Women Chef Cooking Restaurants gardening workshop, barbers With Pockets and Adjustable Strap ( Grey ) | D31: Apron | E31: =IF(ISNUMBER(AD31),IF(AD31>=0,IF(AD31=0,1,INT(AD31/$AC$2)),""),"") -> 1 | F31: =IF(E31="","",IF(AD31=0,0,AD31/$AC$2-E31)) -> 0 | G31: =IF(ISERROR(SEARCH("Apron",D31)),AF31,"") | O31: =IF(ISNUMBER($AF31),1*$AF31,"") | P31: {=XLOOKUP(B31,Weight!B:B,Weight!D:D,"#N/A",0)} -> 140 | Q31: =IF(AF31="","",AF31*P31) | S31: 392620 | T31: 12 | U31: 60 | V31: =B31 -> Apron_Grey | W31: =C31 -> CRASOME Polyester Kitchen Apron for Men Women Chef Cooking Restaurants gardening workshop, barbers With Pockets and Adjustable Strap ( Grey ) | X31: =SUMIFS('Transit Shipment'!$B$10:$B$1048462,'Transit Shipment'!$A$10:$A$1048462,B31,'Transit Shipment'!$C$10:$C$1048462,AA31) -> 0 | Y31: =IF(SUMIFS(DIH!$S$2:$S833,DIH!$D$2:$D833,B31,DIH!$U$2:$U833,AA31)>0,SUMIFS(DIH!$S$2:$S833,DIH!$D$2:$D833,B31,DIH!$U$2:$U833,AA31),0) -> 2 | Z31: =SUM(X31:Y31) -> 2 | AA31: AMD2 | AB31: =IF(ISNA(VLOOKUP($B31,'Business Report'!$D$2:$J$202,2,0)),"",VLOOKUP($B31,'Business Report'!$D$2:$J$202,2,0)) -> 21 | AC31: =SUMIFS(AFS!$P$2:$P$6260,AFS!$N$2:$N$6260,B31,AFS!$AT$2:$AT$6260,AA31) -> 1 | AD31: =CEILING(AC31/$W$2*$X$2,1)-sum(X31:Y31) -> 0 | AF31: =IF(ISNUMBER(AD31),IF(AD31<=0,"",IF(F31="","",E31*$AC$2+IF(F31>0,$AC$2,0))))
A32: APR- Grey | B32: Apron_Grey | C32: CRASOME Polyester Kitchen Apron for Men Women Chef Cooking Restaurants gardening workshop, barbers With Pockets and Adjustable Strap ( Grey ) | D32: Apron | E32: =IF(ISNUMBER(AD32),IF(AD32>=0,IF(AD32=0,1,INT(AD32/$AC$2)),""),"") | F32: =IF(E32="","",IF(AD32=0,0,AD32/$AC$2-E32)) | G32: =IF(ISERROR(SEARCH("Apron",D32)),AF32,"") | O32: =IF(ISNUMBER($AF32),1*$AF32,"") | P32: {=XLOOKUP(B32,Weight!B:B,Weight!D:D,"#N/A",0)} -> 140 | Q32: =IF(AF32="","",AF32*P32) | S32: 392620 | T32: 12 | U32: 60 | X32: =SUMIFS('Transit Shipment'!$B$10:$B$1048462,'Transit Shipment'!$A$10:$A$1048462,B32,'Transit Shipment'!$C$10:$C$1048462,AA32) -> 0 | Y32: =IF(SUMIFS(DIH!$S$2:$S833,DIH!$D$2:$D833,B32,DIH!$U$2:$U833,AA32)>0,SUMIFS(DIH!$S$2:$S833,DIH!$D$2:$D833,B32,DIH!$U$2:$U833,AA32),0) -> 10 | Z32: =SUM(X32:Y32) -> 10 | AA32: BLR8 | AB32: =IF(ISNA(VLOOKUP($B32,'Business Report'!$D$2:$J$202,2,0)),"",VLOOKUP($B32,'Business Report'!$D$2:$J$202,2,0)) -> 21 | AC32: =SUMIFS(AFS!$P$2:$P$6260,AFS!$N$2:$N$6260,B32,AFS!$AT$2:$AT$6260,AA32) -> 2 | AD32: =CEILING(AC32/$W$2*$X$2,1)-sum(X32:Y32) -> -7 | AF32: =IF(ISNUMBER(AD32),IF(AD32<=0,"",IF(F32="","",E32*$AC$2+IF(F32>0,$AC$2,0))))
A33: APR- Grey | B33: Apron_Grey | C33: CRASOME Polyester Kitchen Apron for Men Women Chef Cooking Restaurants gardening workshop, barbers With Pockets and Adjustable Strap ( Grey ) | D33: Apron | E33: =IF(ISNUMBER(AD33),IF(AD33>=0,IF(AD33=0,1,INT(AD33/$AC$2)),""),"") -> 0 | F33: =IF(E33="","",IF(AD33=0,0,AD33/$AC$2-E33)) -> 0.5 | G33: =IF(ISERROR(SEARCH("Apron",D33)),AF33,"") | O33: =IF(ISNUMBER($AF33),1*$AF33,"") -> 2 | P33: {=XLOOKUP(B33,Weight!B:B,Weight!D:D,"#N/A",0)} -> 140 | Q33: =IF(AF33="","",AF33*P33) -> 280 | S33: 392620 | T33: 12 | U33: 60 | X33: =SUMIFS('Transit Shipment'!$B$10:$B$1048462,'Transit Shipment'!$A$10:$A$1048462,B33,'Transit Shipment'!$C$10:$C$1048462,AA33) -> 0 | Y33: =IF(SUMIFS(DIH!$S$2:$S833,DIH!$D$2:$D833,B33,DIH!$U$2:$U833,AA33)>0,SUMIFS(DIH!$S$2:$S833,DIH!$D$2:$D833,B33,DIH!$U$2:$U833,AA33),0) -> 1 | Z33: =SUM(X33:Y33) -> 1 | AA33: BLR7 | AB33: =IF(ISNA(VLOOKUP($B33,'Business Report'!$D$2:$J$202,2,0)),"",VLOOKUP($B33,'Business Report'!$D$2:$J$202,2,0)) -> 21 | AC33: =SUMIFS(AFS!$P$2:$P$6260,AFS!$N$2:$N$6260,B33,AFS!$AT$2:$AT$6260,AA33) -> 1 | AD33: =CEILING(AC33/$W$2*$X$2,1)-sum(X33:Y33) -> 1 | AF33: =IF(ISNUMBER(AD33),IF(AD33<=0,"",IF(F33="","",E33*$AC$2+IF(F33>0,$AC$2,0)))) -> 2
A34: APR- Grey | B34: Apron_Grey | C34: CRASOME Polyester Kitchen Apron for Men Women Chef Cooking Restaurants gardening workshop, barbers With Pockets and Adjustable Strap ( Grey ) | D34: Apron | E34: =IF(ISNUMBER(AD34),IF(AD34>=0,IF(AD34=0,1,INT(AD34/$AC$2)),""),"") | F34: =IF(E34="","",IF(AD34=0,0,AD34/$AC$2-E34)) | G34: =IF(ISERROR(SEARCH("Apron",D34)),AF34,"") | O34: =IF(ISNUMBER($AF34),1*$AF34,"") | P34: {=XLOOKUP(B34,Weight!B:B,Weight!D:D,"#N/A",0)} -> 140 | Q34: =IF(AF34="","",AF34*P34) | S34: 392620 | T34: 12 | U34: 60 | X34: =SUMIFS('Transit Shipment'!$B$10:$B$1048462,'Transit Shipment'!$A$10:$A$1048462,B34,'Transit Shipment'!$C$10:$C$1048462,AA34) -> 0 | Y34: =IF(SUMIFS(DIH!$S$2:$S833,DIH!$D$2:$D833,B34,DIH!$U$2:$U833,AA34)>0,SUMIFS(DIH!$S$2:$S833,DIH!$D$2:$D833,B34,DIH!$U$2:$U833,AA34),0) -> 4 | Z34: =SUM(X34:Y34) -> 4 | AA34: CJB1 | AB34: =IF(ISNA(VLOOKUP($B34,'Business Report'!$D$2:$J$202,2,0)),"",VLOOKUP($B34,'Business Report'!$D$2:$J$202,2,0)) -> 21 | AC34: =SUMIFS(AFS!$P$2:$P$6260,AFS!$N$2:$N$6260,B34,AFS!$AT$2:$AT$6260,AA34) -> 0 | AD34: =CEILING(AC34/$W$2*$X$2,1)-sum(X34:Y34) -> -4 | AF34: =IF(ISNUMBER(AD34),IF(AD34<=0,"",IF(F34="","",E34*$AC$2+IF(F34>0,$AC$2,0))))
A35: APR- Grey | B35: Apron_Grey | C35: CRASOME Polyester Kitchen Apron for Men Women Chef Cooking Restaurants gardening workshop, barbers With Pockets and Adjustable Strap ( Grey ) | D35: Apron | E35: =IF(ISNUMBER(AD35),IF(AD35>=0,IF(AD35=0,1,INT(AD35/$AC$2)),""),"") -> 2 | F35: =IF(E35="","",IF(AD35=0,0,AD35/$AC$2-E35)) -> 0.5 | G35: =IF(ISERROR(SEARCH("Apron",D35)),AF35,"") | O35: =IF(ISNUMBER($AF35),1*$AF35,"") -> 6 | P35: {=XLOOKUP(B35,Weight!B:B,Weight!D:D,"#N/A",0)} -> 140 | Q35: =IF(AF35="","",AF35*P35) -> 840 | S35: 392620 | T35: 12 | U35: 60 | X35: =SUMIFS('Transit Shipment'!$B$10:$B$1048462,'Transit Shipment'!$A$10:$A$1048462,B35,'Transit Shipment'!$C$10:$C$1048462,AA35) -> 0 | Y35: =IF(SUMIFS(DIH!$S$2:$S833,DIH!$D$2:$D833,B35,DIH!$U$2:$U833,AA35)>0,SUMIFS(DIH!$S$2:$S833,DIH!$D$2:$D833,B35,DIH!$U$2:$U833,AA35),0) -> 3 | Z35: =SUM(X35:Y35) -> 3 | AA35: MAA4 | AB35: =IF(ISNA(VLOOKUP($B35,'Business Report'!$D$2:$J$202,2,0)),"",VLOOKUP($B35,'Business Report'!$D$2:$J$202,2,0)) -> 21 | AC35: =SUMIFS(AFS!$P$2:$P$6260,AFS!$N$2:$N$6260,B35,AFS!$AT$2:$AT$6260,AA35) -> 6 | AD35: =CEILING(AC35/$W$2*$X$2,1)-sum(X35:Y35) -> 5 | AF35: =IF(ISNUMBER(AD35),IF(AD35<=0,"",IF(F35="","",E35*$AC$2+IF(F35>0,$AC$2,0)))) -> 6
A36: APR- Grey | B36: Apron_Grey | C36: CRASOME Polyester Kitchen Apron for Men Women Chef Cooking Restaurants gardening workshop, barbers With Pockets and Adjustable Strap ( Grey ) | D36: Apron | E36: =IF(ISNUMBER(AD36),IF(AD36>=0,IF(AD36=0,1,INT(AD36/$AC$2)),""),"") | F36: =IF(E36="","",IF(AD36=0,0,AD36/$AC$2-E36)) | G36: =IF(ISERROR(SEARCH("Apron",D36)),AF36,"") | O36: =IF(ISNUMBER($AF36),1*$AF36,"") | P36: {=XLOOKUP(B36,Weight!B:B,Weight!D:D,"#N/A",0)} -> 140 | Q36: =IF(AF36="","",AF36*P36) | S36: 392620 | T36: 12 | U36: 60 | X36: =SUMIFS('Transit Shipment'!$B$10:$B$1048462,'Transit Shipment'!$A$10:$A$1048462,B36,'Transit Shipment'!$C$10:$C$1048462,AA36) -> 0 | Y36: =IF(SUMIFS(DIH!$S$2:$S833,DIH!$D$2:$D833,B36,DIH!$U$2:$U833,AA36)>0,SUMIFS(DIH!$S$2:$S833,DIH!$D$2:$D833,B36,DIH!$U$2:$U833,AA36),0) -> 3 | Z36: =SUM(X36:Y36) -> 3 | AA36: DEL4 | AB36: =IF(ISNA(VLOOKUP($B36,'Business Report'!$D$2:$J$202,2,0)),"",VLOOKUP($B36,'Business Report'!$D$2:$J$202,2,0)) -> 21 | AC36: =SUMIFS(AFS!$P$2:$P$6260,AFS!$N$2:$N$6260,B36,AFS!$AT$2:$AT$6260,AA36) -> 0 | AD36: =CEILING(AC36/$W$2*$X$2,1)-sum(X36:Y36) -> -3 | AF36: =IF(ISNUMBER(AD36),IF(AD36<=0,"",IF(F36="","",E36*$AC$2+IF(F36>0,$AC$2,0))))
A37: APR- Grey | B37: Apron_Grey | C37: CRASOME Polyester Kitchen Apron for Men Women Chef Cooking Restaurants gardening workshop, barbers With Pockets and Adjustable Strap ( Grey ) | D37: Apron | E37: =IF(ISNUMBER(AD37),IF(AD37>=0,IF(AD37=0,1,INT(AD37/$AC$2)),""),"") | F37: =IF(E37="","",IF(AD37=0,0,AD37/$AC$2-E37)) | G37: =IF(ISERROR(SEARCH("Apron",D37)),AF37,"") | O37: =IF(ISNUMBER($AF37),1*$AF37,"") | P37: {=XLOOKUP(B37,Weight!B:B,Weight!D:D,"#N/A",0)} -> 140 | Q37: =IF(AF37="","",AF37*P37) | S37: 392620 | T37: 12 | U37: 60 | X37: =SUMIFS('Transit Shipment'!$B$10:$B$1048462,'Transit Shipment'!$A$10:$A$1048462,B37,'Transit Shipment'!$C$10:$C$1048462,AA37) -> 0 | Y37: =IF(SUMIFS(DIH!$S$2:$S833,DIH!$D$2:$D833,B37,DIH!$U$2:$U833,AA37)>0,SUMIFS(DIH!$S$2:$S833,DIH!$D$2:$D833,B37,DIH!$U$2:$U833,AA37),0) -> 12 | Z37: =SUM(X37:Y37) -> 12 | AA37: DEL5 | AB37: =IF(ISNA(VLOOKUP($B37,'Business Report'!$D$2:$J$202,2,0)),"",VLOOKUP($B37,'Business Report'!$D$2:$J$202,2,0)) -> 21 | AC37: =SUMIFS(AFS!$P$2:$P$6260,AFS!$N$2:$N$6260,B37,AFS!$AT$2:$AT$6260,AA37) -> 1 | AD37: =CEILING(AC37/$W$2*$X$2,1)-sum(X37:Y37) -> -10 | AF37: =IF(ISNUMBER(AD37),IF(AD37<=0,"",IF(F37="","",E37*$AC$2+IF(F37>0,$AC$2,0))))
A38: APR- Grey | B38: Apron_Grey | C38: CRASOME Polyester Kitchen Apron for Men Women Chef Cooking Restaurants gardening workshop, barbers With Pockets and Adjustable Strap ( Grey ) | D38: Apron | E38: =IF(ISNUMBER(AD38),IF(AD38>=0,IF(AD38=0,1,INT(AD38/$AC$2)),""),"") -> 1 | F38: =IF(E38="","",IF(AD38=0,0,AD38/$AC$2-E38)) -> 0 | G38: =IF(ISERROR(SEARCH("Apron",D38)),AF38,"") | O38: =IF(ISNUMBER($AF38),1*$AF38,"") | P38: {=XLOOKUP(B38,Weight!B:B,Weight!D:D,"#N/A",0)} -> 140 | Q38: =IF(AF38="","",AF38*P38) | S38: 392620 | T38: 12 | U38: 60 | X38: =SUMIFS('Transit Shipment'!$B$10:$B$1048462,'Transit Shipment'!$A$10:$A$1048462,B38,'Transit Shipment'!$C$10:$C$1048462,AA38) -> 0 | Y38: =IF(SUMIFS(DIH!$S$2:$S833,DIH!$D$2:$D833,B38,DIH!$U$2:$U833,AA38)>0,SUMIFS(DIH!$S$2:$S833,DIH!$D$2:$D833,B38,DIH!$U$2:$U833,AA38),0) -> 2 | Z38: =SUM(X38:Y38) -> 2 | AA38: BOM5 | AB38: =IF(ISNA(VLOOKUP($B38,'Business Report'!$D$2:$J$202,2,0)),"",VLOOKUP($B38,'Business Report'!$D$2:$J$202,2,0)) -> 21 | AC38: =SUMIFS(AFS!$P$2:$P$6260,AFS!$N$2:$N$6260,B38,AFS!$AT$2:$AT$6260,AA38) -> 1 | AD38: =CEILING(AC38/$W$2*$X$2,1)-sum(X38:Y38) -> 0 | AF38: =IF(ISNUMBER(AD38),IF(AD38<=0,"",IF(F38="","",E38*$AC$2+IF(F38>0,$AC$2,0))))
A39: APR- Grey | B39: Apron_Grey | C39: CRASOME Polyester Kitchen Apron for Men Women Chef Cooking Restaurants gardening workshop, barbers With Pockets and Adjustable Strap ( Grey ) | D39: Apron | E39: =IF(ISNUMBER(AD39),IF(AD39>=0,IF(AD39=0,1,INT(AD39/$AC$2)),""),"") -> 1 | F39: =IF(E39="","",IF(AD39=0,0,AD39/$AC$2-E39)) -> 0 | G39: =IF(ISERROR(SEARCH("Apron",D39)),AF39,"") | O39: =IF(ISNUMBER($AF39),1*$AF39,"") | P39: {=XLOOKUP(B39,Weight!B:B,Weight!D:D,"#N/A",0)} -> 140 | Q39: =IF(AF39="","",AF39*P39) | S39: 392620 | T39: 12 | U39: 60 | X39: =SUMIFS('Transit Shipment'!$B$10:$B$1048462,'Transit Shipment'!$A$10:$A$1048462,B39,'Transit Shipment'!$C$10:$C$1048462,AA39) -> 0 | Y39: =IF(SUMIFS(DIH!$S$2:$S833,DIH!$D$2:$D833,B39,DIH!$U$2:$U833,AA39)>0,SUMIFS(DIH!$S$2:$S833,DIH!$D$2:$D833,B39,DIH!$U$2:$U833,AA39),0) -> 0 | Z39: =SUM(X39:Y39) -> 0 | AA39: BOM7 | AB39: =IF(ISNA(VLOOKUP($B39,'Business Report'!$D$2:$J$202,2,0)),"",VLOOKUP($B39,'Business Report'!$D$2:$J$202,2,0)) -> 21 | AC39: =SUMIFS(AFS!$P$2:$P$6260,AFS!$N$2:$N$6260,B39,AFS!$AT$2:$AT$6260,AA39) -> 0 | AD39: =CEILING(AC39/$W$2*$X$2,1)-sum(X39:Y39) -> 0 | AE39: =SUM(AD31:AD39) -> -18 | AF39: =IF(ISNUMBER(AD39),IF(AD39<=0,"",IF(F39="","",E39*$AC$2+IF(F39>0,$AC$2,0))))
A40: APR- Red | B40: Apron_Red | C40: CRASOME Polyester Kitchen Apron for Men Women Chef Cooking Restaurants gardening workshop, barbers With Pockets and Adjustable Strap ( Red ) | D40: Apron | E40: =IF(ISNUMBER(AD40),IF(AD40>=0,IF(AD40=0,1,INT(AD40/$AC$2)),""),"") -> 1 | F40: =IF(E40="","",IF(AD40=0,0,AD40/$AC$2-E40)) -> 0 | G40: =IF(ISERROR(SEARCH("Apron",D40)),AF40,"") | N40: =IF(ISNUMBER($AF40),1*$AF40,"") | P40: {=XLOOKUP(B40,Weight!B:B,Weight!D:D,"#N/A",0)} -> 140 | Q40: =IF(AF40="","",AF40*P40) | S40: 392620 | T40: 12 | U40: 60 | V40: =B40 -> Apron_Red | W40: =C40 -> CRASOME Polyester Kitchen Apron for Men Women Chef Cooking Restaurants gardening workshop, barbers With Pockets and Adjustable Strap ( Red ) | X40: =SUMIFS('Transit Shipment'!$B$10:$B$1048462,'Transit Shipment'!$A$10:$A$1048462,B40,'Transit Shipment'!$C$10:$C$1048462,AA40) -> 0 | Y40: =IF(SUMIFS(DIH!$S$2:$S833,DIH!$D$2:$D833,B40,DIH!$U$2:$U833,AA40)>0,SUMIFS(DIH!$S$2:$S833,DIH!$D$2:$D833,B40,DIH!$U$2:$U833,AA40),0) -> 0 | Z40: =SUM(X40:Y40) -> 0 | AA40: AMD2 | AB40: =IF(ISNA(VLOOKUP($B40,'Business Report'!$D$2:$J$202,2,0)),"",VLOOKUP($B40,'Business Report'!$D$2:$J$202,2,0)) -> 12 | AC40: =SUMIFS(AFS!$P$2:$P$6260,AFS!$N$2:$N$6260,B40,AFS!$AT$2:$AT$6260,AA40) -> 0 | AD40: =CEILING(AC40/$W$2*$X$2,1)-sum(X40:Y40) -> 0 | AF40: =IF(ISNUMBER(AD40),IF(AD40<=0,"",IF(F40="","",E40*$AC$2+IF(F40>0,$AC$2,0))))
...

Sheet Sheet13
A1: Apron_Black | B1: {=UNIQUE(A1:A819)} -> Apron_Black
A2: Apron_Black | B2: Apron_Blue
A3: Apron_Black | B3: Apron_Brown
A4: Apron_Black | B4: Apron_Grey
A5: Apron_Black | B5: Apron_Red
A6: Apron_Black | B6: CRM_AP_TAN
A7: Apron_Black | B7: CRM_AP_GREEN
A8: Apron_Black | B8: CRM_AP_BLACK_PACK OF 2
A9: Apron_Black | B9: CRM_AP_BLUE_PACK OF 2
A10: Apron_Blue | B10: CRM_AP_BROWN_PACK OF 2
A11: Apron_Blue | B11: CRM_AP_GREEN_PACK OF 2
A12: Apron_Blue | B12: CRM_AP_GREY_PACK OF 2
A13: Apron_Blue | B13: CRM_AP_RED_PACK OF 2
... A91: CRM_AP_GREEN_PACK OF 2 | B91: CRM-Cube1-Grey-Pack3-1
A92: CRM_AP_GREEN_PACK OF 2
A93: CRM_AP_GREEN_PACK OF 2
A94: CRM_AP_GREEN_PACK OF 2
A95: CRM_AP_GREEN_PACK OF 2
A96: CRM_AP_GREEN_PACK OF 2
A97: CRM_AP_GREEN_PACK OF 2
A98: CRM_AP_GREEN_PACK OF 2
A99: CRM_AP_GREEN_PACK OF 2
A100: CRM_AP_GREY_PACK OF 2
A101: CRM_AP_GREY_PACK OF 2
A102: CRM_AP_GREY_PACK OF 2
A103: CRM_AP_GREY_PACK OF 2
... A819: CRM-Cube1-Grey-Pack3-1

Sheet Stock
E1: Total Actual Qty | G1: =sum(F3:F1001) -> 3532 | I1: {=IF(OR(G1<>SUM(INDIRECT("Calculation!G3:O")), G1<>Boxes!C52), "Error", "")} -> Error | K1: Sep | L1: =IF(MONTH(DATEVALUE(K1&" 1"))<>MONTH(TODAY()), "Change Url Stock Manager", "") -> Change Url Stock Manager | M1: Url ----->> | N1: 1xsE5TY9L1oXdnssxXiLmdN0LEb2tXUlxQPtf5qE-9rI
A2: Model | B2: SKU | C2: Required Qty | E2: Model | F2: Required Qty | G2: Available Qty | H2: Diffrence | K2: =IFERROR(__xludf.DUMMYFUNCTION("IMPORTRANGE(N1,""Monthly Avg.!A1:T200"")"),"") | N2: =IFERROR(__xludf.DUMMYFUNCTION("""COMPUTED_VALUE"""),"CRASOME (Sep '25)") -> CRASOME (Sep '25) | X2: =IFERROR(__xludf.DUMMYFUNCTION("""COMPUTED_VALUE"""),"Total Debit of current month") -> Total Debit of current month | Y2: =IFERROR(__xludf.DUMMYFUNCTION("""COMPUTED_VALUE"""),"Aug '25 Closing Balance") -> Aug '25 Closing Balance
A3: APR- Sky Blue | C3: =sum(Calculation!$H$4:$H1001) -> 0 | E3: =IFERROR(__xludf.DUMMYFUNCTION("UNIQUE(FILTER(A3:A1001, C3:C1001 <> 0))"),"APR- Dark Blue") -> APR- Dark Blue | F3: =SUMIF(A:A,E3,C:C) -> 122 | G3: =XLOOKUP(E3,K:K,Q:Q) -> 1766 | H3: =G3-F3 -> 1644 | K3: =IFERROR(__xludf.DUMMYFUNCTION("""COMPUTED_VALUE"""),"Model") -> Model | M3: =IFERROR(__xludf.DUMMYFUNCTION("""COMPUTED_VALUE"""),"Category") -> Category | N3: =IFERROR(__xludf.DUMMYFUNCTION("""COMPUTED_VALUE"""),"Owner") -> Owner | O3: =IFERROR(__xludf.DUMMYFUNCTION("""COMPUTED_VALUE"""),"Req.Stock") -> Req.Stock | P3: =IFERROR(__xludf.DUMMYFUNCTION("""COMPUTED_VALUE"""),"Avg.") -> Avg. | Q3: =IFERROR(__xludf.DUMMYFUNCTION("""COMPUTED_VALUE"""),"Balance") -> Balance | R3: =IFERROR(__xludf.DUMMYFUNCTION("""COMPUTED_VALUE"""),"Total Month") -> Total Month | S3: =IFERROR(__xludf.DUMMYFUNCTION("""COMPUTED_VALUE"""),"Apr") -> Apr | T3: =IFERROR(__xludf.DUMMYFUNCTION("""COMPUTED_VALUE"""),"May") -> May | U3: =IFERROR(__xludf.DUMMYFUNCTION("""COMPUTED_VALUE"""),"June") -> June | V3: =IFERROR(__xludf.DUMMYFUNCTION("""COMPUTED_VALUE"""),"July") -> July | W3: =IFERROR(__xludf.DUMMYFUNCTION("""COMPUTED_VALUE"""),"Aug") -> Aug | Y3: =IFERROR(__xludf.DUMMYFUNCTION("""COMPUTED_VALUE"""),"Balance") -> Balance | AB3: =IFERROR(__xludf.DUMMYFUNCTION("""COMPUTED_VALUE"""),"Monthly Avg. Multipler (Advance Stock)") -> Monthly Avg. Multipler (Advance Stock)
A4: APR- Dark Blue | C4: =sum(Calculation!$I$4:$I1001) -> 122 | E4: =IFERROR(__xludf.DUMMYFUNCTION("""COMPUTED_VALUE"""),"APR- Brown") -> APR- Brown | F4: =SUMIF(A:A,E4,C:C) -> 102 | G4: =XLOOKUP(E4,K:K,Q:Q) -> 1363 | H4: =G4-F4 -> 1261 | K4: =IFERROR(__xludf.DUMMYFUNCTION("""COMPUTED_VALUE"""),"Ultra") -> Ultra | M4: =IFERROR(__xludf.DUMMYFUNCTION("""COMPUTED_VALUE"""),"Printer") -> Printer | N4: =IFERROR(__xludf.DUMMYFUNCTION("""COMPUTED_VALUE"""),"AG") -> AG | O4: =IFERROR(__xludf.DUMMYFUNCTION("""COMPUTED_VALUE"""),0.0) -> 0 | P4: =IFERROR(__xludf.DUMMYFUNCTION("""COMPUTED_VALUE"""),0.0) -> 0 | Q4: =IFERROR(__xludf.DUMMYFUNCTION("""COMPUTED_VALUE"""),0.0) -> 0 | R4: =IFERROR(__xludf.DUMMYFUNCTION("""COMPUTED_VALUE"""),5.0) -> 5 | S4: =IFERROR(__xludf.DUMMYFUNCTION("""COMPUTED_VALUE"""),0.0) -> 0 | T4: =IFERROR(__xludf.DUMMYFUNCTION("""COMPUTED_VALUE"""),0.0) -> 0 | U4: =IFERROR(__xludf.DUMMYFUNCTION("""COMPUTED_VALUE"""),0.0) -> 0 | V4: =IFERROR(__xludf.DUMMYFUNCTION("""COMPUTED_VALUE"""),0.0) -> 0 | W4: =IFERROR(__xludf.DUMMYFUNCTION("""COMPUTED_VALUE"""),0.0) -> 0 | X4: =IFERROR(__xludf.DUMMYFUNCTION("""COMPUTED_VALUE"""),0.0) -> 0 | Y4: =IFERROR(__xludf.DUMMYFUNCTION("""COMPUTED_VALUE"""),0.0) -> 0 | Z4: =IFERROR(__xludf.DUMMYFUNCTION("""COMPUTED_VALUE"""),"Discontinued") -> Discontinued
A5: APR- Brown | C5: =sum(Calculation!$J$4:$J1001) -> 102 | E5: =IFERROR(__xludf.DUMMYFUNCTION("""COMPUTED_VALUE"""),"APR- Green") -> APR- Green | F5: =SUMIF(A:A,E5,C:C) -> 64 | G5: =XLOOKUP(E5,K:K,Q:Q) -> 965 | H5: =G5-F5 -> 901 | K5: =IFERROR(__xludf.DUMMYFUNCTION("""COMPUTED_VALUE"""),"BAJAJ") -> BAJAJ | M5: =IFERROR(__xludf.DUMMYFUNCTION("""COMPUTED_VALUE"""),"Printer") -> Printer | N5: =IFERROR(__xludf.DUMMYFUNCTION("""COMPUTED_VALUE"""),"AG") -> AG | O5: =IFERROR(__xludf.DUMMYFUNCTION("""COMPUTED_VALUE"""),-14.0) -> -14 | P5: =IFERROR(__xludf.DUMMYFUNCTION("""COMPUTED_VALUE"""),221.0) -> 221 | Q5: =IFERROR(__xludf.DUMMYFUNCTION("""COMPUTED_VALUE"""),235.0) -> 235 | R5: =IFERROR(__xludf.DUMMYFUNCTION("""COMPUTED_VALUE"""),5.0) -> 5 | S5: =IFERROR(__xludf.DUMMYFUNCTION("""COMPUTED_VALUE"""),182.0) -> 182 | T5: =IFERROR(__xludf.DUMMYFUNCTION("""COMPUTED_VALUE"""),37.0) -> 37 | U5: =IFERROR(__xludf.DUMMYFUNCTION("""COMPUTED_VALUE"""),93.0) -> 93 | V5: =IFERROR(__xludf.DUMMYFUNCTION("""COMPUTED_VALUE"""),140.0) -> 140 | W5: =IFERROR(__xludf.DUMMYFUNCTION("""COMPUTED_VALUE"""),283.0) -> 283 | X5: =IFERROR(__xludf.DUMMYFUNCTION("""COMPUTED_VALUE"""),151.0) -> 151 | Y5: =IFERROR(__xludf.DUMMYFUNCTION("""COMPUTED_VALUE"""),383.0) -> 383 | AB5: =IFERROR(__xludf.DUMMYFUNCTION("""COMPUTED_VALUE"""),1.5) -> 1.5
A6: APR- Green | C6: =sum(Calculation!$K$4:$K1001) -> 64 | E6: =IFERROR(__xludf.DUMMYFUNCTION("""COMPUTED_VALUE"""),"APR- Tan") -> APR- Tan | F6: =SUMIF(A:A,E6,C:C) -> 152 | G6: =XLOOKUP(E6,K:K,Q:Q) -> 1447 | H6: =G6-F6 -> 1295 | K6: =IFERROR(__xludf.DUMMYFUNCTION("""COMPUTED_VALUE"""),"WG") -> WG | M6: =IFERROR(__xludf.DUMMYFUNCTION("""COMPUTED_VALUE"""),"WG") -> WG | N6: =IFERROR(__xludf.DUMMYFUNCTION("""COMPUTED_VALUE"""),"AG") -> AG | O6: =IFERROR(__xludf.DUMMYFUNCTION("""COMPUTED_VALUE"""),-34.0) -> -34 | P6: =IFERROR(__xludf.DUMMYFUNCTION("""COMPUTED_VALUE"""),0.0) -> 0 | Q6: =IFERROR(__xludf.DUMMYFUNCTION("""COMPUTED_VALUE"""),34.0) -> 34 | R6: =IFERROR(__xludf.DUMMYFUNCTION("""COMPUTED_VALUE"""),5.0) -> 5 | S6: =IFERROR(__xludf.DUMMYFUNCTION("""COMPUTED_VALUE"""),0.0) -> 0 | T6: =IFERROR(__xludf.DUMMYFUNCTION("""COMPUTED_VALUE"""),0.0) -> 0 | U6: =IFERROR(__xludf.DUMMYFUNCTION("""COMPUTED_VALUE"""),0.0) -> 0 | V6: =IFERROR(__xludf.DUMMYFUNCTION("""COMPUTED_VALUE"""),0.0) -> 0 | W6: =IFERROR(__xludf.DUMMYFUNCTION("""COMPUTED_VALUE"""),0.0) -> 0 | X6: =IFERROR(__xludf.DUMMYFUNCTION("""COMPUTED_VALUE"""),0.0) -> 0 | Y6: =IFERROR(__xludf.DUMMYFUNCTION("""COMPUTED_VALUE"""),34.0) -> 34 | Z6: =IFERROR(__xludf.DUMMYFUNCTION("""COMPUTED_VALUE"""),"Discontinued") -> Discontinued
A7: APR- Tan | C7: =sum(Calculation!$L$4:$L1001) -> 152 | E7: =IFERROR(__xludf.DUMMYFUNCTION("""COMPUTED_VALUE"""),"APR- Black") -> APR- Black | F7: =SUMIF(A:A,E7,C:C) -> 128 | G7: =XLOOKUP(E7,K:K,Q:Q) -> 2649 | H7: =G7-F7 -> 2521
A8: APR- Black | C8: =sum(Calculation!$M$4:$M1001) -> 128 | E8: =IFERROR(__xludf.DUMMYFUNCTION("""COMPUTED_VALUE"""),"APR- Red") -> APR- Red | F8: =SUMIF(A:A,E8,C:C) -> 38 | G8: =XLOOKUP(E8,K:K,Q:Q) -> 892 | H8: =G8-F8 -> 854 | K8: =IFERROR(__xludf.DUMMYFUNCTION("""COMPUTED_VALUE"""),"M200") -> M200 | M8: =IFERROR(__xludf.DUMMYFUNCTION("""COMPUTED_VALUE"""),"Printer") -> Printer | N8: =IFERROR(__xludf.DUMMYFUNCTION("""COMPUTED_VALUE"""),"AG") -> AG | O8: =IFERROR(__xludf.DUMMYFUNCTION("""COMPUTED_VALUE"""),-3.0) -> -3 | P8: =IFERROR(__xludf.DUMMYFUNCTION("""COMPUTED_VALUE"""),0.0) -> 0 | Q8: =IFERROR(__xludf.DUMMYFUNCTION("""COMPUTED_VALUE"""),3.0) -> 3 | R8: =IFERROR(__xludf.DUMMYFUNCTION("""COMPUTED_VALUE"""),5.0) -> 5 | S8: =IFERROR(__xludf.DUMMYFUNCTION("""COMPUTED_VALUE"""),0.0) -> 0 | T8: =IFERROR(__xludf.DUMMYFUNCTION("""COMPUTED_VALUE"""),0.0) -> 0 | U8: =IFERROR(__xludf.DUMMYFUNCTION("""COMPUTED_VALUE"""),0.0) -> 0 | V8: =IFERROR(__xludf.DUMMYFUNCTION("""COMPUTED_VALUE"""),0.0) -> 0 | W8: =IFERROR(__xludf.DUMMYFUNCTION("""COMPUTED_VALUE"""),0.0) -> 0 | X8: =IFERROR(__xludf.DUMMYFUNCTION("""COMPUTED_VALUE"""),0.0) -> 0 | Y8: =IFERROR(__xludf.DUMMYFUNCTION("""COMPUTED_VALUE"""),3.0) -> 3 | Z8: =IFERROR(__xludf.DUMMYFUNCTION("""COMPUTED_VALUE"""),"Discontinued") -> Discontinued | AB8: =IFERROR(__xludf.DUMMYFUNCTION("""COMPUTED_VALUE"""),1.0) -> 1
A9: APR- Red | C9: =sum(Calculation!$N$4:$N1001) -> 38 | E9: =IFERROR(__xludf.DUMMYFUNCTION("""COMPUTED_VALUE"""),"APR- Grey") -> APR- Grey | F9: =SUMIF(A:A,E9,C:C) -> 28 | G9: =XLOOKUP(E9,K:K,Q:Q) -> 582 | H9: =G9-F9 -> 554 | K9: =IFERROR(__xludf.DUMMYFUNCTION("""COMPUTED_VALUE"""),"HP 3-4") -> HP 3-4 | M9: =IFERROR(__xludf.DUMMYFUNCTION("""COMPUTED_VALUE"""),"Printer") -> Printer | N9: =IFERROR(__xludf.DUMMYFUNCTION("""COMPUTED_VALUE"""),"AG") -> AG | O9: =IFERROR(__xludf.DUMMYFUNCTION("""COMPUTED_VALUE"""),-14.0) -> -14 | P9: =IFERROR(__xludf.DUMMYFUNCTION("""COMPUTED_VALUE"""),0.0) -> 0 | Q9: =IFERROR(__xludf.DUMMYFUNCTION("""COMPUTED_VALUE"""),14.0) -> 14 | R9: =IFERROR(__xludf.DUMMYFUNCTION("""COMPUTED_VALUE"""),5.0) -> 5 | S9: =IFERROR(__xludf.DUMMYFUNCTION("""COMPUTED_VALUE"""),0.0) -> 0 | T9: =IFERROR(__xludf.DUMMYFUNCTION("""COMPUTED_VALUE"""),0.0) -> 0 | U9: =IFERROR(__xludf.DUMMYFUNCTION("""COMPUTED_VALUE"""),0.0) -> 0 | V9: =IFERROR(__xludf.DUMMYFUNCTION("""COMPUTED_VALUE"""),0.0) -> 0 | W9: =IFERROR(__xludf.DUMMYFUNCTION("""COMPUTED_VALUE"""),0.0) -> 0 | X9: =IFERROR(__xludf.DUMMYFUNCTION("""COMPUTED_VALUE"""),0.0) -> 0 | Y9: =IFERROR(__xludf.DUMMYFUNCTION("""COMPUTED_VALUE"""),14.0) -> 14 | Z9: =IFERROR(__xludf.DUMMYFUNCTION("""COMPUTED_VALUE"""),"Discontinued") -> Discontinued | AB9: =IFERROR(__xludf.DUMMYFUNCTION("""COMPUTED_VALUE"""),1.0) -> 1
A10: APR- Grey | C10: =sum(Calculation!$O$4:$O1001) -> 28 | E10: =IFERROR(__xludf.DUMMYFUNCTION("""COMPUTED_VALUE"""),"BAJAJ") -> BAJAJ | F10: =SUMIF(A:A,E10,C:C) -> 158 | G10: =XLOOKUP(E10,K:K,Q:Q) -> 235 | H10: =G10-F10 -> 77 | K10: =IFERROR(__xludf.DUMMYFUNCTION("""COMPUTED_VALUE"""),"CanonG") -> CanonG | M10: =IFERROR(__xludf.DUMMYFUNCTION("""COMPUTED_VALUE"""),"Printer") -> Printer | N10: =IFERROR(__xludf.DUMMYFUNCTION("""COMPUTED_VALUE"""),"AG") -> AG | O10: =IFERROR(__xludf.DUMMYFUNCTION("""COMPUTED_VALUE"""),-70.0) -> -70 | P10: =IFERROR(__xludf.DUMMYFUNCTION("""COMPUTED_VALUE"""),2.0) -> 2 | Q10: =IFERROR(__xludf.DUMMYFUNCTION("""COMPUTED_VALUE"""),72.0) -> 72 | R10: =IFERROR(__xludf.DUMMYFUNCTION("""COMPUTED_VALUE"""),5.0) -> 5 | S10: =IFERROR(__xludf.DUMMYFUNCTION("""COMPUTED_VALUE"""),1.0) -> 1 | T10: =IFERROR(__xludf.DUMMYFUNCTION("""COMPUTED_VALUE"""),2.0) -> 2 | U10: =IFERROR(__xludf.DUMMYFUNCTION("""COMPUTED_VALUE"""),2.0) -> 2 | V10: =IFERROR(__xludf.DUMMYFUNCTION("""COMPUTED_VALUE"""),0.0) -> 0 | W10: =IFERROR(__xludf.DUMMYFUNCTION("""COMPUTED_VALUE"""),1.0) -> 1 | X10: =IFERROR(__xludf.DUMMYFUNCTION("""COMPUTED_VALUE"""),4.0) -> 4 | Y10: =IFERROR(__xludf.DUMMYFUNCTION("""COMPUTED_VALUE"""),75.0) -> 75 | Z10: =IFERROR(__xludf.DUMMYFUNCTION("""COMPUTED_VALUE"""),"Discontinued") -> Discontinued | AB10: =IFERROR(__xludf.DUMMYFUNCTION("""COMPUTED_VALUE"""),1.25) -> 1.25
